<mujoco model="inspire_robots_rh56dftp_left">
  <compiler angle="radian" autolimits="true" meshdir="assets"/>

  <asset>
    <material name="white" rgba="1 1 1 1"/>
    <material name="gray" rgba="0.4 0.4 0.4 1"/>

    <mesh file="base_link.stl"/>
    <mesh file="palm_force_sensor.stl"/>
    <mesh file="left_thumb_1.stl"/>
    <mesh file="left_thumb_2.stl"/>
    <mesh file="thumb_force_sensor_1.stl"/>
    <mesh file="left_thumb_3.stl"/>
    <mesh file="thumb_force_sensor_2.stl"/>
    <mesh file="left_thumb_4.stl"/>
    <mesh file="thumb_force_sensor_3.stl"/>
    <mesh file="thumb_force_sensor_4.stl"/>
    <mesh file="left_index_1.stl"/>
    <mesh file="index_force_sensor_1.stl"/>
    <mesh file="left_index_2.stl"/>
    <mesh file="index_force_sensor_2.stl"/>
    <mesh file="index_force_sensor_3.stl"/>
    <mesh file="left_middle_1.stl"/>
    <mesh file="middle_force_sensor_1.stl"/>
    <mesh file="left_middle_2.stl"/>
    <mesh file="middle_force_sensor_2.stl"/>
    <mesh file="middle_force_sensor_3.stl"/>
    <mesh file="left_ring_1.stl"/>
    <mesh file="ring_force_sensor_1.stl"/>
    <mesh file="left_ring_2.stl"/>
    <mesh file="ring_force_sensor_2.stl"/>
    <mesh file="ring_force_sensor_3.stl"/>
    <mesh file="left_little_1.stl"/>
    <mesh file="little_force_sensor_1.stl"/>
    <mesh file="left_little_2.stl"/>
    <mesh file="little_force_sensor_2.stl"/>
    <mesh file="little_force_sensor_3.stl"/>
  </asset>

  <default>
    <default class="rh56dftp">
      <geom type="mesh" material="white"/>
    </default>
  </default>

  <worldbody>
    <body name="base_link" pos="0 0 0" childclass="rh56dftp">
      <geom type="mesh" mesh="base_link"/>
      <geom pos="0.00036819 0.012296 0.1196" quat="-2.59734e-06 -2.59735e-06 0.707108 0.707105" type="mesh" material="gray" mesh="palm_force_sensor"/>
      <body name="left_thumb_1" pos="0.0269 0.02101 0.0689">
        <inertial pos="0.000892587 0.000344905 0.00159994" quat="0.985466 0.00605548 0.115048 0.124838" mass="0.00746" diaginertia="1.34891e-07 1.09691e-07 6.68155e-08"/>
        <joint name="left_thumb_1_joint" pos="0 0 0" axis="0 0 1" range="0 1.1641" actuatorfrcrange="-10 10"/>
        <geom type="mesh" mesh="left_thumb_1"/>
        <body name="left_thumb_2" pos="0.0073431 0.011232 0.0052" quat="0.0922934 0.0922938 -0.701059 -0.701056">
          <inertial pos="-0.0141191 0.0118389 -0.0088672" quat="0.152261 0.678876 -0.168783 0.698181" mass="0.04364" diaginertia="1.52495e-06 1.17176e-06 1.06745e-06"/>
          <joint name="left_thumb_2_joint" pos="0 0 0" axis="0 0 -1" range="0 0.5864" actuatorfrcrange="-10 10"/>
          <geom type="mesh" mesh="left_thumb_2"/>
          <geom pos="-0.0087121 0.026305 -0.0089605" quat="0.405917 -0.578993 -0.405916 -0.578991" type="mesh" material="gray" mesh="thumb_force_sensor_1"/>
          <body name="left_thumb_3" pos="-0.031403 0.021069 -0.001299">
            <inertial pos="-0.0106831 0.00293204 -0.0079803" quat="0.630491 0.725992 0.273308 -0.0268299" mass="0.01601" diaginertia="1.03234e-06 9.80921e-07 4.62549e-07"/>
            <joint name="left_thumb_3_joint" pos="0 0 0" axis="0 0 -1" range="0 0.5" actuatorfrcrange="-10 10"/>
            <geom type="mesh" mesh="left_thumb_3"/>
            <geom pos="-0.011771 0.01699 -0.0077514" quat="0.428302 -0.562766 -0.428175 -0.562599" type="mesh" material="gray" mesh="thumb_force_sensor_2"/>
            <body name="left_thumb_4" pos="-0.021903 0.012816 -0.0003">
              <inertial pos="-0.0154206 0.00325953 -0.00981932" quat="0.509539 0.730741 0.454295 -0.00191329" mass="0.01172" diaginertia="2.01225e-06 1.78327e-06 7.11257e-07"/>
              <joint name="left_thumb_4_joint" pos="0 0 0" axis="0 0 -1" range="0 3.14" actuatorfrcrange="-10 10"/>
              <geom type="mesh" mesh="left_thumb_4"/>
              <geom pos="-0.014598 0.014721 -0.0073103" quat="0.348432 -0.615302 -0.348433 -0.615299" type="mesh" material="gray" mesh="thumb_force_sensor_3"/>
              <geom pos="-0.028987 0.017301 -0.0073513" quat="-0.356218 0.610827 -0.356216 -0.610827" type="mesh" material="gray" mesh="thumb_force_sensor_4"/>
            </body>
          </body>
        </body>
      </body>
      <body name="left_index_1" pos="0.038679 0.00056467 0.1564" quat="0.508647 0.491199 -0.491201 -0.508648">
        <inertial pos="-0.0027798 0.0120616 0.00599425" quat="0.335314 0.231303 -0.81565 0.410827" mass="0.02941" diaginertia="2.19245e-06 1.8452e-06 8.88525e-07"/>
        <joint name="left_index_1_joint" pos="0 0 0" axis="0 0 1" range="0 1.4381" actuatorfrcrange="-10 10"/>
        <geom type="mesh" mesh="left_index_1"/>
        <geom pos="-0.012046 0.019649 0.006651" quat="0.701686 -0.0622873 -0.704358 -0.0873853" type="mesh" material="gray" mesh="index_force_sensor_1"/>
        <body name="left_index_2" pos="-0.0034259 0.032596 0.00055">
          <inertial pos="-0.00156369 0.0175358 0.00500993" quat="0.396288 0.415196 -0.594023 0.563654" mass="0.01418" diaginertia="1.00912e-05 8.43434e-06 1.98804e-06"/>
          <joint name="left_index_2_joint" pos="0 0 0" axis="0 0 1" range="0 3.14" actuatorfrcrange="-10 10"/>
          <geom type="mesh" mesh="left_index_2"/>
          <geom pos="-0.0081655 0.037446 0.0060795" quat="0.698536 0.13559 -0.693985 0.109758" type="mesh" material="gray" mesh="index_force_sensor_2"/>
          <geom pos="-0.0086237 0.052572 0.0060954" quat="0.658743 -0.226725 -0.669773 -0.257017" type="mesh" material="gray" mesh="index_force_sensor_3"/>
        </body>
      </body>
      <body name="left_middle_1" pos="0.0171 0.00056467 0.157" quat="0.499998 0.5 -0.500002 -0.5">
        <inertial pos="-0.00278814 0.0120854 0.00599425" quat="0.338048 0.229333 -0.817612 0.40576" mass="0.02941" diaginertia="2.17435e-06 1.81621e-06 8.99186e-07"/>
        <joint name="left_middle_1_joint" pos="0 0 0" axis="0 0 1" range="0 1.4381" actuatorfrcrange="-10 10"/>
        <geom type="mesh" mesh="left_middle_1"/>
        <geom pos="-0.012046 0.019649 0.006651" quat="0.703134 -0.0748456 -0.703135 -0.0748437" type="mesh" material="gray" mesh="middle_force_sensor_1"/>
        <body name="left_middle_2" pos="-0.0034259 0.032596 0.00055">
          <inertial pos="-0.00206152 0.0203704 0.00493141" quat="0.402299 0.423075 -0.602547 0.544152" mass="0.01761" diaginertia="1.1944e-05 1.00683e-05 2.23451e-06"/>
          <joint name="left_middle_2_joint" pos="0 0 0" axis="0 0 1" range="0 3.14" actuatorfrcrange="-10 10"/>
          <geom type="mesh" mesh="left_middle_2"/>
          <geom pos="-0.009086 0.040962 0.0061003" quat="0.694858 0.131041 -0.694858 0.131044" type="mesh" material="gray" mesh="middle_force_sensor_2"/>
          <geom pos="-0.0098294 0.056051 0.0061006" quat="0.667288 -0.233938 -0.667289 -0.233936" type="mesh" material="gray" mesh="middle_force_sensor_3"/>
        </body>
      </body>
      <body name="left_ring_1" pos="-0.0045302 0.00056467 0.15683" quat="0.486728 0.512927 -0.512929 -0.48673">
        <inertial pos="-0.00279904 0.0121214 0.00599425" quat="0.341657 0.226163 -0.820695 0.398222" mass="0.02941" diaginertia="2.14701e-06 1.77247e-06 9.1533e-07"/>
        <joint name="left_ring_1_joint" pos="0 0 0" axis="0 0 1" range="0 1.4381" actuatorfrcrange="-10 10"/>
        <geom type="mesh" mesh="left_ring_1"/>
        <geom pos="-0.012046 0.019649 0.006651" quat="0.704887 -0.0936618 -0.700876 -0.0559809" type="mesh" material="gray" mesh="ring_force_sensor_1"/>
        <body name="left_ring_2" pos="-0.0034259 0.032596 0.00055">
          <inertial pos="-0.00191784 0.0180594 0.00504847" quat="0.408379 0.398611 -0.604779 0.555499" mass="0.01481" diaginertia="1.00053e-05 8.41672e-06 1.9262e-06"/>
          <joint name="left_ring_2_joint" pos="0 0 0" axis="0 0 1" range="0 3.14" actuatorfrcrange="-10 10"/>
          <geom type="mesh" mesh="left_ring_2"/>
          <geom pos="-0.0081655 0.037446 0.0060795" quat="0.692694 0.103257 -0.699527 0.142038" type="mesh" material="gray" mesh="ring_force_sensor_2"/>
          <geom pos="-0.0086237 0.052572 0.0060954" quat="0.6723 -0.264487 -0.655779 -0.219118" type="mesh" material="gray" mesh="ring_force_sensor_3"/>
        </body>
      </body>
      <body name="left_little_1" pos="-0.025916 0.00056467 0.15365" quat="0.47315 0.525478 -0.52548 -0.473152">
        <inertial pos="-0.00280799 0.012158 0.00599425" quat="0.34468 0.222753 -0.823943 0.390763" mass="0.02941" diaginertia="2.11947e-06 1.72847e-06 9.31639e-07"/>
        <joint name="left_little_1_joint" pos="0 0 0" axis="0 0 1" range="0 1.4381" actuatorfrcrange="-10 10"/>
        <geom type="mesh" mesh="left_little_1"/>
        <geom pos="-0.012046 0.019649 0.006651" quat="0.706132 -0.112374 -0.69812 -0.0371073" type="mesh" material="gray" mesh="little_force_sensor_1"/>
        <body name="left_little_2" pos="-0.0034259 0.032596 0.00055">
          <inertial pos="-0.00124753 0.0130025 0.00463411" quat="0.400355 0.386309 -0.630274 0.541512" mass="0.01157" diaginertia="6.18511e-06 5.27433e-06 1.16308e-06"/>
          <joint name="left_little_2_joint" pos="0 0 0" axis="0 0 1" range="0 3.14" actuatorfrcrange="-10 10"/>
          <geom type="mesh" mesh="left_little_2"/>
          <geom pos="-0.0064514 0.027683 0.0061172" quat="0.689046 0.0814204 -0.702404 0.158792" type="mesh" material="gray" mesh="little_force_sensor_2"/>
          <geom pos="-0.0063973 0.042707 0.0061154" quat="0.678772 -0.289133 -0.645293 -0.198161" type="mesh" material="gray" mesh="little_force_sensor_3"/>
        </body>
      </body>
    </body>
  </worldbody>
</mujoco>
