<mujoco model="scene">
  <compiler angle="radian" alignfree="true"/>

  <option timestep="0.001" o_solref="0.002 1" integrator="implicit" cone="elliptic">
    <flag override="enable" multiccd="enable"/>
  </option>

  <size nkey="1"/>

  <visual>
    <global azimuth="-90" elevation="-30"/>
    <quality shadowsize="16384"/>
    <headlight diffuse="0.6 0.6 0.6" specular="0 0 0"/>
    <rgba haze="0.15 0.25 0.35 1"/>
  </visual>

  <statistic extent="1.1" center="0 0 0.1"/>

  <default>
    <default class="table/main"/>
    <default class="robot_torso/main">
      <default class="robot_torso/visual">
        <geom type="mesh" contype="0" conaffinity="0" group="2"/>
      </default>
      <default class="robot_torso/collision">
        <geom type="mesh" group="3"/>
      </default>
    </default>
    <default class="xarm7_left/main">
      <default class="xarm7_left/xarm7">
        <joint range="-6.28319 6.28319" armature="0.1" frictionloss="1"/>
        <geom type="mesh" material="white"/>
        <site size="0.001 0.005 0.005" group="4" rgba="1 0 0 1"/>
        <general ctrlrange="-6.28319 6.28319" biastype="affine"/>
        <default class="xarm7_left/size1">
          <joint damping="10"/>
          <general forcerange="-50 50" gainprm="1500" biasprm="0 -1500 -150"/>
        </default>
        <default class="xarm7_left/size2">
          <joint damping="5"/>
          <general forcerange="-30 30" gainprm="1000" biasprm="0 -1000 -100"/>
        </default>
        <default class="xarm7_left/size3">
          <joint damping="2"/>
          <general forcerange="-20 20" gainprm="800" biasprm="0 -800 -80"/>
        </default>
      </default>
      <default class="xarm7_left/inspire_rh56dftp_left/main">
        <default class="xarm7_left/inspire_rh56dftp_left/visual">
          <geom type="mesh" contype="0" conaffinity="0" group="2" material="white"/>
          <default class="xarm7_left/inspire_rh56dftp_left/visual_force_sensor">
            <geom material="black"/>
          </default>
        </default>
        <default class="xarm7_left/inspire_rh56dftp_left/collision">
          <geom type="mesh" group="3" material="white"/>
          <default class="xarm7_left/inspire_rh56dftp_left/collision_force_sensor">
            <geom material="black"/>
          </default>
        </default>
        <default class="xarm7_left/inspire_rh56dftp_left/base">
          <joint damping="0.1"/>
          <default class="xarm7_left/inspire_rh56dftp_left/thumb_proximal_1">
            <joint range="0 1.1641"/>
            <general ctrlrange="0 1.1641" biastype="affine" biasprm="0 -1"/>
          </default>
          <default class="xarm7_left/inspire_rh56dftp_left/thumb_proximal_2">
            <joint range="0 0.5864"/>
            <general ctrlrange="0 0.5864" biastype="affine" biasprm="0 -1"/>
          </default>
          <default class="xarm7_left/inspire_rh56dftp_left/thumb_middle">
            <joint range="0 0.5"/>
            <general ctrlrange="0 0.5" biastype="affine" biasprm="0 -1"/>
          </default>
          <default class="xarm7_left/inspire_rh56dftp_left/thumb_distal">
            <joint range="0 0.5"/>
            <general ctrlrange="0 0.5" biastype="affine" biasprm="0 -1"/>
          </default>
          <default class="xarm7_left/inspire_rh56dftp_left/proximal">
            <joint range="0 1.4381"/>
            <general ctrlrange="0 1.4381" biastype="affine" biasprm="0 -1"/>
          </default>
          <default class="xarm7_left/inspire_rh56dftp_left/distal">
            <joint range="0 1.4381"/>
            <general ctrlrange="0 1.4381" biastype="affine" biasprm="0 -1"/>
          </default>
        </default>
      </default>
    </default>
    <default class="xarm7_right/main">
      <default class="xarm7_right/xarm7">
        <joint range="-6.28319 6.28319" armature="0.1" frictionloss="1"/>
        <geom type="mesh" material="white"/>
        <site size="0.001 0.005 0.005" group="4" rgba="1 0 0 1"/>
        <general ctrlrange="-6.28319 6.28319" biastype="affine"/>
        <default class="xarm7_right/size1">
          <joint damping="10"/>
          <general forcerange="-50 50" gainprm="1500" biasprm="0 -1500 -150"/>
        </default>
        <default class="xarm7_right/size2">
          <joint damping="5"/>
          <general forcerange="-30 30" gainprm="1000" biasprm="0 -1000 -100"/>
        </default>
        <default class="xarm7_right/size3">
          <joint damping="2"/>
          <general forcerange="-20 20" gainprm="800" biasprm="0 -800 -80"/>
        </default>
      </default>
      <default class="xarm7_right/inspire_rh56dftp_right/main">
        <default class="xarm7_right/inspire_rh56dftp_right/visual">
          <geom type="mesh" contype="0" conaffinity="0" group="2" material="white"/>
          <default class="xarm7_right/inspire_rh56dftp_right/visual_force_sensor"/>
        </default>
        <default class="xarm7_right/inspire_rh56dftp_right/collision">
          <geom type="mesh" group="3" material="white"/>
          <default class="xarm7_right/inspire_rh56dftp_right/collision_force_sensor"/>
        </default>
        <default class="xarm7_right/inspire_rh56dftp_right/base">
          <joint damping="0.1"/>
          <default class="xarm7_right/inspire_rh56dftp_right/thumb_proximal_1">
            <joint range="0 1.1641"/>
            <general ctrlrange="0 1.1641" biastype="affine" biasprm="0 -1"/>
          </default>
          <default class="xarm7_right/inspire_rh56dftp_right/thumb_proximal_2">
            <joint range="0 0.5864"/>
            <general ctrlrange="0 0.5864" biastype="affine" biasprm="0 -1"/>
          </default>
          <default class="xarm7_right/inspire_rh56dftp_right/thumb_middle">
            <joint range="0 0.5"/>
            <general ctrlrange="0 0.5" biastype="affine" biasprm="0 -1"/>
          </default>
          <default class="xarm7_right/inspire_rh56dftp_right/thumb_distal">
            <joint range="0 0.5"/>
            <general ctrlrange="0 0.5" biastype="affine" biasprm="0 -1"/>
          </default>
          <default class="xarm7_right/inspire_rh56dftp_right/proximal">
            <joint range="0 1.4381"/>
            <general ctrlrange="0 1.4381" biastype="affine" biasprm="0 -1"/>
          </default>
          <default class="xarm7_right/inspire_rh56dftp_right/distal">
            <joint range="0 1.4381"/>
            <general ctrlrange="0 1.4381" biastype="affine" biasprm="0 -1"/>
          </default>
        </default>
      </default>
    </default>
    <default class="barcode_scanner/main">
      <geom condim="6" priority="1"/>
      <default class="barcode_scanner/visual">
        <geom type="mesh" contype="0" conaffinity="0" condim="3" group="2" priority="0"/>
      </default>
      <default class="barcode_scanner/collision">
        <geom type="mesh" condim="3" group="3" priority="0"/>
      </default>
    </default>
    <default class="003_cracker_box/main">
      <geom condim="6" priority="1"/>
      <default class="003_cracker_box/visual">
        <geom type="mesh" contype="0" conaffinity="0" condim="3" group="2" priority="0"/>
      </default>
      <default class="003_cracker_box/collision">
        <geom type="mesh" condim="3" group="3" priority="0"/>
      </default>
    </default>
    <default class="004_sugar_box/main">
      <geom condim="6" priority="1"/>
      <default class="004_sugar_box/visual">
        <geom type="mesh" contype="0" conaffinity="0" condim="3" group="2" priority="0"/>
      </default>
      <default class="004_sugar_box/collision">
        <geom type="mesh" condim="3" group="3" priority="0"/>
      </default>
    </default>
    <default class="005_tomato_soup_can/main">
      <geom condim="6" priority="1"/>
      <default class="005_tomato_soup_can/visual">
        <geom type="mesh" contype="0" conaffinity="0" condim="3" group="2" priority="0"/>
      </default>
      <default class="005_tomato_soup_can/collision">
        <geom type="mesh" condim="3" group="3" priority="0"/>
      </default>
    </default>
    <default class="006_mustard_bottle/main">
      <geom condim="6" priority="1"/>
      <default class="006_mustard_bottle/visual">
        <geom type="mesh" contype="0" conaffinity="0" condim="3" group="2" priority="0"/>
      </default>
      <default class="006_mustard_bottle/collision">
        <geom type="mesh" condim="3" group="3" priority="0"/>
      </default>
    </default>
    <default class="010_potted_meat_can/main">
      <geom condim="6" priority="1"/>
      <default class="010_potted_meat_can/visual">
        <geom type="mesh" contype="0" conaffinity="0" condim="3" group="2" priority="0"/>
      </default>
      <default class="010_potted_meat_can/collision">
        <geom type="mesh" condim="3" group="3" priority="0"/>
      </default>
    </default>
    <default class="021_bleach_cleanser/main">
      <geom condim="6" priority="1"/>
      <default class="021_bleach_cleanser/visual">
        <geom type="mesh" contype="0" conaffinity="0" condim="3" group="2" priority="0"/>
      </default>
      <default class="021_bleach_cleanser/collision">
        <geom type="mesh" condim="3" group="3" priority="0"/>
      </default>
    </default>
  </default>

  <asset>
    <texture type="skybox" colorspace="auto" builtin="gradient" rgb1="0.3 0.5 0.7" rgb2="0 0 0" width="512" height="3072"/>
    <texture type="2d" colorspace="auto" name="groundplane" builtin="checker" mark="edge" rgb1="0.2 0.3 0.4" rgb2="0.1 0.2 0.3" markrgb="0.8 0.8 0.8" width="300" height="300"/>
    <texture type="2d" colorspace="linear" name="barcode_scanner/barcode_scanner" file="barcode_scanner.png"/>
    <texture type="2d" colorspace="linear" name="003_cracker_box/texture_map" file="texture_map.png"/>
    <texture type="2d" colorspace="linear" name="004_sugar_box/texture_map" file="texture_map.png"/>
    <texture type="2d" colorspace="linear" name="005_tomato_soup_can/texture_map" file="texture_map.png"/>
    <texture type="2d" colorspace="linear" name="006_mustard_bottle/texture_map" file="texture_map.png"/>
    <texture type="2d" colorspace="linear" name="010_potted_meat_can/texture_map" file="texture_map.png"/>
    <texture type="2d" colorspace="linear" name="021_bleach_cleanser/texture_map" file="texture_map.png"/>
    <material name="groundplane" texture="groundplane" texuniform="true" texrepeat="5 5" reflectance="0.2"/>
    <material name="xarm7_left/white"/>
    <material name="xarm7_left/gray" rgba="0.753 0.753 0.753 1"/>
    <material name="xarm7_left/inspire_rh56dftp_left/black" rgba="0.2 0.2 0.2 1"/>
    <material name="xarm7_left/inspire_rh56dftp_left/white" rgba="0.9 0.9 0.9 1"/>
    <material name="xarm7_right/white"/>
    <material name="xarm7_right/gray" rgba="0.753 0.753 0.753 1"/>
    <material name="xarm7_right/inspire_rh56dftp_right/black" rgba="0.2 0.2 0.2 1"/>
    <material name="xarm7_right/inspire_rh56dftp_right/white" rgba="0.9 0.9 0.9 1"/>
    <material name="barcode_scanner/material_0" texture="barcode_scanner/barcode_scanner" specular="1" shininess="1"/>
    <material name="003_cracker_box/material_0" texture="003_cracker_box/texture_map"/>
    <material name="004_sugar_box/material_0" texture="004_sugar_box/texture_map"/>
    <material name="005_tomato_soup_can/material_0" texture="005_tomato_soup_can/texture_map"/>
    <material name="006_mustard_bottle/material_0" texture="006_mustard_bottle/texture_map"/>
    <material name="010_potted_meat_can/material_0" texture="010_potted_meat_can/texture_map"/>
    <material name="021_bleach_cleanser/material_0" texture="021_bleach_cleanser/texture_map"/>
    <mesh name="table/table" content_type="model/stl" file="table.stl"/>
    <mesh name="robot_torso/robot_torso" content_type="model/obj" file="robot_torso.obj"/>
    <mesh name="robot_torso/robot_torso_collision_0" content_type="model/obj" file="robot_torso_collision_0.obj"/>
    <mesh name="robot_torso/robot_torso_collision_1" content_type="model/obj" file="robot_torso_collision_1.obj"/>
    <mesh name="robot_torso/robot_torso_collision_2" content_type="model/obj" file="robot_torso_collision_2.obj"/>
    <mesh name="robot_torso/robot_torso_collision_3" content_type="model/obj" file="robot_torso_collision_3.obj"/>
    <mesh name="robot_torso/robot_torso_collision_4" content_type="model/obj" file="robot_torso_collision_4.obj"/>
    <mesh name="robot_torso/robot_torso_collision_5" content_type="model/obj" file="robot_torso_collision_5.obj"/>
    <mesh name="robot_torso/robot_torso_collision_6" content_type="model/obj" file="robot_torso_collision_6.obj"/>
    <mesh name="robot_torso/robot_torso_collision_7" content_type="model/obj" file="robot_torso_collision_7.obj"/>
    <mesh name="robot_torso/robot_torso_collision_8" content_type="model/obj" file="robot_torso_collision_8.obj"/>
    <mesh name="robot_torso/robot_torso_collision_9" content_type="model/obj" file="robot_torso_collision_9.obj"/>
    <mesh name="robot_torso/robot_torso_collision_10" content_type="model/obj" file="robot_torso_collision_10.obj"/>
    <mesh name="robot_torso/robot_torso_collision_11" content_type="model/obj" file="robot_torso_collision_11.obj"/>
    <mesh name="robot_torso/robot_torso_collision_12" content_type="model/obj" file="robot_torso_collision_12.obj"/>
    <mesh name="xarm7_left/link_base" content_type="model/stl" file="link_base.stl"/>
    <mesh name="xarm7_left/link1" content_type="model/stl" file="link1.stl"/>
    <mesh name="xarm7_left/link2" content_type="model/stl" file="link2.stl"/>
    <mesh name="xarm7_left/link3" content_type="model/stl" file="link3.stl"/>
    <mesh name="xarm7_left/link4" content_type="model/stl" file="link4.stl"/>
    <mesh name="xarm7_left/link5" content_type="model/stl" file="link5.stl"/>
    <mesh name="xarm7_left/link6" content_type="model/stl" file="link6.stl"/>
    <mesh name="xarm7_left/link7" content_type="model/stl" file="link7.stl"/>
    <mesh name="xarm7_left/end_tool" content_type="model/stl" file="end_tool.stl"/>
    <mesh name="xarm7_left/inspire_rh56dftp_left/base_link" content_type="model/obj" file="base_link.obj"/>
    <mesh name="xarm7_left/inspire_rh56dftp_left/thumb_proximal_1" content_type="model/obj" file="thumb_proximal_1.obj"/>
    <mesh name="xarm7_left/inspire_rh56dftp_left/thumb_proximal_2" content_type="model/obj" file="thumb_proximal_2.obj"/>
    <mesh name="xarm7_left/inspire_rh56dftp_left/thumb_middle" content_type="model/obj" file="thumb_middle.obj"/>
    <mesh name="xarm7_left/inspire_rh56dftp_left/thumb_distal" content_type="model/obj" file="thumb_distal.obj"/>
    <mesh name="xarm7_left/inspire_rh56dftp_left/index_proximal" content_type="model/obj" file="index_proximal.obj"/>
    <mesh name="xarm7_left/inspire_rh56dftp_left/index_distal" content_type="model/obj" file="index_distal.obj"/>
    <mesh name="xarm7_left/inspire_rh56dftp_left/middle_proximal" content_type="model/obj" file="middle_proximal.obj"/>
    <mesh name="xarm7_left/inspire_rh56dftp_left/middle_distal" content_type="model/obj" file="middle_distal.obj"/>
    <mesh name="xarm7_left/inspire_rh56dftp_left/ring_proximal" content_type="model/obj" file="ring_proximal.obj"/>
    <mesh name="xarm7_left/inspire_rh56dftp_left/ring_distal" content_type="model/obj" file="ring_distal.obj"/>
    <mesh name="xarm7_left/inspire_rh56dftp_left/little_proximal" content_type="model/obj" file="little_proximal.obj"/>
    <mesh name="xarm7_left/inspire_rh56dftp_left/little_distal" content_type="model/obj" file="little_distal.obj"/>
    <mesh name="xarm7_left/inspire_rh56dftp_left/palm_force_sensor" content_type="model/obj" file="palm_force_sensor.obj"/>
    <mesh name="xarm7_left/inspire_rh56dftp_left/thumb_proximal_force_sensor" content_type="model/obj" file="thumb_proximal_force_sensor.obj"/>
    <mesh name="xarm7_left/inspire_rh56dftp_left/thumb_middle_force_sensor" content_type="model/obj" file="thumb_middle_force_sensor.obj"/>
    <mesh name="xarm7_left/inspire_rh56dftp_left/thumb_distal_force_sensor" content_type="model/obj" file="thumb_distal_force_sensor.obj"/>
    <mesh name="xarm7_left/inspire_rh56dftp_left/thumb_fingertip_force_sensor" content_type="model/obj" file="thumb_fingertip_force_sensor.obj"/>
    <mesh name="xarm7_left/inspire_rh56dftp_left/index_proximal_force_sensor" content_type="model/obj" file="index_proximal_force_sensor.obj"/>
    <mesh name="xarm7_left/inspire_rh56dftp_left/index_distal_force_sensor" content_type="model/obj" file="index_distal_force_sensor.obj"/>
    <mesh name="xarm7_left/inspire_rh56dftp_left/index_fingertip_force_sensor" content_type="model/obj" file="index_fingertip_force_sensor.obj"/>
    <mesh name="xarm7_left/inspire_rh56dftp_left/middle_proximal_force_sensor" content_type="model/obj" file="middle_proximal_force_sensor.obj"/>
    <mesh name="xarm7_left/inspire_rh56dftp_left/middle_distal_force_sensor" content_type="model/obj" file="middle_distal_force_sensor.obj"/>
    <mesh name="xarm7_left/inspire_rh56dftp_left/middle_fingertip_force_sensor" content_type="model/obj" file="middle_fingertip_force_sensor.obj"/>
    <mesh name="xarm7_left/inspire_rh56dftp_left/ring_proximal_force_sensor" content_type="model/obj" file="ring_proximal_force_sensor.obj"/>
    <mesh name="xarm7_left/inspire_rh56dftp_left/ring_distal_force_sensor" content_type="model/obj" file="ring_distal_force_sensor.obj"/>
    <mesh name="xarm7_left/inspire_rh56dftp_left/ring_fingertip_force_sensor" content_type="model/obj" file="ring_fingertip_force_sensor.obj"/>
    <mesh name="xarm7_left/inspire_rh56dftp_left/little_proximal_force_sensor" content_type="model/obj" file="little_proximal_force_sensor.obj"/>
    <mesh name="xarm7_left/inspire_rh56dftp_left/little_distal_force_sensor" content_type="model/obj" file="little_distal_force_sensor.obj"/>
    <mesh name="xarm7_left/inspire_rh56dftp_left/little_fingertip_force_sensor" content_type="model/obj" file="little_fingertip_force_sensor.obj"/>
    <mesh name="xarm7_right/link_base" file="link_base.stl"/>
    <mesh name="xarm7_right/link1" file="link1.stl"/>
    <mesh name="xarm7_right/link2" file="link2.stl"/>
    <mesh name="xarm7_right/link3" file="link3.stl"/>
    <mesh name="xarm7_right/link4" file="link4.stl"/>
    <mesh name="xarm7_right/link5" file="link5.stl"/>
    <mesh name="xarm7_right/link6" file="link6.stl"/>
    <mesh name="xarm7_right/link7" file="link7.stl"/>
    <mesh name="xarm7_right/end_tool" file="end_tool.stl"/>
    <mesh name="xarm7_right/inspire_rh56dftp_right/base_link" content_type="model/obj" file="base_link.obj"/>
    <mesh name="xarm7_right/inspire_rh56dftp_right/thumb_proximal_1" content_type="model/obj" file="thumb_proximal_1.obj"/>
    <mesh name="xarm7_right/inspire_rh56dftp_right/thumb_proximal_2" content_type="model/obj" file="thumb_proximal_2.obj"/>
    <mesh name="xarm7_right/inspire_rh56dftp_right/thumb_middle" content_type="model/obj" file="thumb_middle.obj"/>
    <mesh name="xarm7_right/inspire_rh56dftp_right/thumb_distal" content_type="model/obj" file="thumb_distal.obj"/>
    <mesh name="xarm7_right/inspire_rh56dftp_right/index_proximal" content_type="model/obj" file="index_proximal.obj"/>
    <mesh name="xarm7_right/inspire_rh56dftp_right/index_distal" content_type="model/obj" file="index_distal.obj"/>
    <mesh name="xarm7_right/inspire_rh56dftp_right/middle_proximal" content_type="model/obj" file="middle_proximal.obj"/>
    <mesh name="xarm7_right/inspire_rh56dftp_right/middle_distal" content_type="model/obj" file="middle_distal.obj"/>
    <mesh name="xarm7_right/inspire_rh56dftp_right/ring_proximal" content_type="model/obj" file="ring_proximal.obj"/>
    <mesh name="xarm7_right/inspire_rh56dftp_right/ring_distal" content_type="model/obj" file="ring_distal.obj"/>
    <mesh name="xarm7_right/inspire_rh56dftp_right/little_proximal" content_type="model/obj" file="little_proximal.obj"/>
    <mesh name="xarm7_right/inspire_rh56dftp_right/little_distal" content_type="model/obj" file="little_distal.obj"/>
    <mesh name="xarm7_right/inspire_rh56dftp_right/palm_force_sensor" content_type="model/obj" file="palm_force_sensor.obj"/>
    <mesh name="xarm7_right/inspire_rh56dftp_right/thumb_proximal_force_sensor" content_type="model/obj" file="thumb_proximal_force_sensor.obj"/>
    <mesh name="xarm7_right/inspire_rh56dftp_right/thumb_middle_force_sensor" content_type="model/obj" file="thumb_middle_force_sensor.obj"/>
    <mesh name="xarm7_right/inspire_rh56dftp_right/thumb_distal_force_sensor" content_type="model/obj" file="thumb_distal_force_sensor.obj"/>
    <mesh name="xarm7_right/inspire_rh56dftp_right/thumb_fingertip_force_sensor" content_type="model/obj" file="thumb_fingertip_force_sensor.obj"/>
    <mesh name="xarm7_right/inspire_rh56dftp_right/index_proximal_force_sensor" content_type="model/obj" file="index_proximal_force_sensor.obj"/>
    <mesh name="xarm7_right/inspire_rh56dftp_right/index_distal_force_sensor" content_type="model/obj" file="index_distal_force_sensor.obj"/>
    <mesh name="xarm7_right/inspire_rh56dftp_right/index_fingertip_force_sensor" content_type="model/obj" file="index_fingertip_force_sensor.obj"/>
    <mesh name="xarm7_right/inspire_rh56dftp_right/middle_proximal_force_sensor" content_type="model/obj" file="middle_proximal_force_sensor.obj"/>
    <mesh name="xarm7_right/inspire_rh56dftp_right/middle_distal_force_sensor" content_type="model/obj" file="middle_distal_force_sensor.obj"/>
    <mesh name="xarm7_right/inspire_rh56dftp_right/middle_fingertip_force_sensor" content_type="model/obj" file="middle_fingertip_force_sensor.obj"/>
    <mesh name="xarm7_right/inspire_rh56dftp_right/ring_proximal_force_sensor" content_type="model/obj" file="ring_proximal_force_sensor.obj"/>
    <mesh name="xarm7_right/inspire_rh56dftp_right/ring_distal_force_sensor" content_type="model/obj" file="ring_distal_force_sensor.obj"/>
    <mesh name="xarm7_right/inspire_rh56dftp_right/ring_fingertip_force_sensor" content_type="model/obj" file="ring_fingertip_force_sensor.obj"/>
    <mesh name="xarm7_right/inspire_rh56dftp_right/little_proximal_force_sensor" content_type="model/obj" file="little_proximal_force_sensor.obj"/>
    <mesh name="xarm7_right/inspire_rh56dftp_right/little_distal_force_sensor" content_type="model/obj" file="little_distal_force_sensor.obj"/>
    <mesh name="xarm7_right/inspire_rh56dftp_right/little_fingertip_force_sensor" content_type="model/obj" file="little_fingertip_force_sensor.obj"/>
    <mesh name="barcode_scanner/barcode_scanner" content_type="model/obj" file="barcode_scanner.obj"/>
    <mesh name="barcode_scanner/barcode_scanner_collision_0" content_type="model/obj" file="barcode_scanner_collision_0.obj"/>
    <mesh name="barcode_scanner/barcode_scanner_collision_1" content_type="model/obj" file="barcode_scanner_collision_1.obj"/>
    <mesh name="barcode_scanner/barcode_scanner_collision_2" content_type="model/obj" file="barcode_scanner_collision_2.obj"/>
    <mesh name="barcode_scanner/barcode_scanner_collision_3" content_type="model/obj" file="barcode_scanner_collision_3.obj"/>
    <mesh name="barcode_scanner/barcode_scanner_collision_4" content_type="model/obj" file="barcode_scanner_collision_4.obj"/>
    <mesh name="barcode_scanner/barcode_scanner_collision_5" content_type="model/obj" file="barcode_scanner_collision_5.obj"/>
    <mesh name="barcode_scanner/barcode_scanner_collision_6" content_type="model/obj" file="barcode_scanner_collision_6.obj"/>
    <mesh name="barcode_scanner/barcode_scanner_collision_7" content_type="model/obj" file="barcode_scanner_collision_7.obj"/>
    <mesh name="barcode_scanner/barcode_scanner_collision_8" content_type="model/obj" file="barcode_scanner_collision_8.obj"/>
    <mesh name="barcode_scanner/barcode_scanner_collision_9" content_type="model/obj" file="barcode_scanner_collision_9.obj"/>
    <mesh name="barcode_scanner/barcode_scanner_collision_10" content_type="model/obj" file="barcode_scanner_collision_10.obj"/>
    <mesh name="barcode_scanner/barcode_scanner_collision_11" content_type="model/obj" file="barcode_scanner_collision_11.obj"/>
    <mesh name="barcode_scanner/barcode_scanner_collision_12" content_type="model/obj" file="barcode_scanner_collision_12.obj"/>
    <mesh name="barcode_scanner/barcode_scanner_collision_13" content_type="model/obj" file="barcode_scanner_collision_13.obj"/>
    <mesh name="barcode_scanner/barcode_scanner_collision_14" content_type="model/obj" file="barcode_scanner_collision_14.obj"/>
    <mesh name="barcode_scanner/barcode_scanner_collision_15" content_type="model/obj" file="barcode_scanner_collision_15.obj"/>
    <mesh name="barcode_scanner/barcode_scanner_collision_16" content_type="model/obj" file="barcode_scanner_collision_16.obj"/>
    <mesh name="barcode_scanner/barcode_scanner_collision_17" content_type="model/obj" file="barcode_scanner_collision_17.obj"/>
    <mesh name="barcode_scanner/barcode_scanner_collision_18" content_type="model/obj" file="barcode_scanner_collision_18.obj"/>
    <mesh name="barcode_scanner/barcode_scanner_collision_19" content_type="model/obj" file="barcode_scanner_collision_19.obj"/>
    <mesh name="barcode_scanner/barcode_scanner_collision_20" content_type="model/obj" file="barcode_scanner_collision_20.obj"/>
    <mesh name="barcode_scanner/barcode_scanner_collision_21" content_type="model/obj" file="barcode_scanner_collision_21.obj"/>
    <mesh name="barcode_scanner/barcode_scanner_collision_22" content_type="model/obj" file="barcode_scanner_collision_22.obj"/>
    <mesh name="barcode_scanner/barcode_scanner_collision_23" content_type="model/obj" file="barcode_scanner_collision_23.obj"/>
    <mesh name="barcode_scanner/barcode_scanner_collision_24" content_type="model/obj" file="barcode_scanner_collision_24.obj"/>
    <mesh name="barcode_scanner/barcode_scanner_collision_25" content_type="model/obj" file="barcode_scanner_collision_25.obj"/>
    <mesh name="barcode_scanner/barcode_scanner_collision_26" content_type="model/obj" file="barcode_scanner_collision_26.obj"/>
    <mesh name="barcode_scanner/barcode_scanner_collision_27" content_type="model/obj" file="barcode_scanner_collision_27.obj"/>
    <mesh name="barcode_scanner/barcode_scanner_collision_28" content_type="model/obj" file="barcode_scanner_collision_28.obj"/>
    <mesh name="barcode_scanner/barcode_scanner_collision_29" content_type="model/obj" file="barcode_scanner_collision_29.obj"/>
    <mesh name="barcode_scanner/barcode_scanner_collision_30" content_type="model/obj" file="barcode_scanner_collision_30.obj"/>
    <mesh name="barcode_scanner/barcode_scanner_collision_31" content_type="model/obj" file="barcode_scanner_collision_31.obj"/>
    <mesh name="barcode_scanner/barcode_scanner_collision_32" content_type="model/obj" file="barcode_scanner_collision_32.obj"/>
    <mesh name="barcode_scanner/barcode_scanner_collision_33" content_type="model/obj" file="barcode_scanner_collision_33.obj"/>
    <mesh name="barcode_scanner/barcode_scanner_collision_34" content_type="model/obj" file="barcode_scanner_collision_34.obj"/>
    <mesh name="barcode_scanner/barcode_scanner_collision_35" content_type="model/obj" file="barcode_scanner_collision_35.obj"/>
    <mesh name="barcode_scanner/barcode_scanner_collision_36" content_type="model/obj" file="barcode_scanner_collision_36.obj"/>
    <mesh name="barcode_scanner/barcode_scanner_collision_37" content_type="model/obj" file="barcode_scanner_collision_37.obj"/>
    <mesh name="barcode_scanner/barcode_scanner_collision_38" content_type="model/obj" file="barcode_scanner_collision_38.obj"/>
    <mesh name="barcode_scanner/barcode_scanner_collision_39" content_type="model/obj" file="barcode_scanner_collision_39.obj"/>
    <mesh name="barcode_scanner/barcode_scanner_collision_40" content_type="model/obj" file="barcode_scanner_collision_40.obj"/>
    <mesh name="barcode_scanner/barcode_scanner_collision_41" content_type="model/obj" file="barcode_scanner_collision_41.obj"/>
    <mesh name="barcode_scanner/barcode_scanner_collision_42" content_type="model/obj" file="barcode_scanner_collision_42.obj"/>
    <mesh name="barcode_scanner/barcode_scanner_collision_43" content_type="model/obj" file="barcode_scanner_collision_43.obj"/>
    <mesh name="barcode_scanner/barcode_scanner_collision_44" content_type="model/obj" file="barcode_scanner_collision_44.obj"/>
    <mesh name="barcode_scanner/barcode_scanner_collision_45" content_type="model/obj" file="barcode_scanner_collision_45.obj"/>
    <mesh name="barcode_scanner/barcode_scanner_collision_46" content_type="model/obj" file="barcode_scanner_collision_46.obj"/>
    <mesh name="barcode_scanner/barcode_scanner_collision_47" content_type="model/obj" file="barcode_scanner_collision_47.obj"/>
    <mesh name="barcode_scanner/barcode_scanner_collision_48" content_type="model/obj" file="barcode_scanner_collision_48.obj"/>
    <mesh name="barcode_scanner/barcode_scanner_collision_49" content_type="model/obj" file="barcode_scanner_collision_49.obj"/>
    <mesh name="barcode_scanner/barcode_scanner_collision_50" content_type="model/obj" file="barcode_scanner_collision_50.obj"/>
    <mesh name="barcode_scanner/barcode_scanner_collision_51" content_type="model/obj" file="barcode_scanner_collision_51.obj"/>
    <mesh name="barcode_scanner/barcode_scanner_collision_52" content_type="model/obj" file="barcode_scanner_collision_52.obj"/>
    <mesh name="barcode_scanner/barcode_scanner_collision_53" content_type="model/obj" file="barcode_scanner_collision_53.obj"/>
    <mesh name="barcode_scanner/barcode_scanner_collision_54" content_type="model/obj" file="barcode_scanner_collision_54.obj"/>
    <mesh name="barcode_scanner/barcode_scanner_collision_55" content_type="model/obj" file="barcode_scanner_collision_55.obj"/>
    <mesh name="barcode_scanner/barcode_scanner_collision_56" content_type="model/obj" file="barcode_scanner_collision_56.obj"/>
    <mesh name="barcode_scanner/barcode_scanner_collision_57" content_type="model/obj" file="barcode_scanner_collision_57.obj"/>
    <mesh name="barcode_scanner/barcode_scanner_collision_58" content_type="model/obj" file="barcode_scanner_collision_58.obj"/>
    <mesh name="barcode_scanner/barcode_scanner_collision_59" content_type="model/obj" file="barcode_scanner_collision_59.obj"/>
    <mesh name="barcode_scanner/barcode_scanner_collision_60" content_type="model/obj" file="barcode_scanner_collision_60.obj"/>
    <mesh name="barcode_scanner/barcode_scanner_collision_61" content_type="model/obj" file="barcode_scanner_collision_61.obj"/>
    <mesh name="barcode_scanner/barcode_scanner_collision_62" content_type="model/obj" file="barcode_scanner_collision_62.obj"/>
    <mesh name="barcode_scanner/barcode_scanner_collision_63" content_type="model/obj" file="barcode_scanner_collision_63.obj"/>
    <mesh name="barcode_scanner/barcode_scanner_collision_64" content_type="model/obj" file="barcode_scanner_collision_64.obj"/>
    <mesh name="barcode_scanner/barcode_scanner_collision_65" content_type="model/obj" file="barcode_scanner_collision_65.obj"/>
    <mesh name="barcode_scanner/barcode_scanner_collision_66" content_type="model/obj" file="barcode_scanner_collision_66.obj"/>
    <mesh name="barcode_scanner/barcode_scanner_collision_67" content_type="model/obj" file="barcode_scanner_collision_67.obj"/>
    <mesh name="barcode_scanner/barcode_scanner_collision_68" content_type="model/obj" file="barcode_scanner_collision_68.obj"/>
    <mesh name="barcode_scanner/barcode_scanner_collision_69" content_type="model/obj" file="barcode_scanner_collision_69.obj"/>
    <mesh name="barcode_scanner/barcode_scanner_collision_70" content_type="model/obj" file="barcode_scanner_collision_70.obj"/>
    <mesh name="barcode_scanner/barcode_scanner_collision_71" content_type="model/obj" file="barcode_scanner_collision_71.obj"/>
    <mesh name="barcode_scanner/barcode_scanner_collision_72" content_type="model/obj" file="barcode_scanner_collision_72.obj"/>
    <mesh name="barcode_scanner/barcode_scanner_collision_73" content_type="model/obj" file="barcode_scanner_collision_73.obj"/>
    <mesh name="barcode_scanner/barcode_scanner_collision_74" content_type="model/obj" file="barcode_scanner_collision_74.obj"/>
    <mesh name="barcode_scanner/barcode_scanner_collision_75" content_type="model/obj" file="barcode_scanner_collision_75.obj"/>
    <mesh name="barcode_scanner/barcode_scanner_collision_76" content_type="model/obj" file="barcode_scanner_collision_76.obj"/>
    <mesh name="barcode_scanner/barcode_scanner_collision_77" content_type="model/obj" file="barcode_scanner_collision_77.obj"/>
    <mesh name="barcode_scanner/barcode_scanner_collision_78" content_type="model/obj" file="barcode_scanner_collision_78.obj"/>
    <mesh name="barcode_scanner/barcode_scanner_collision_79" content_type="model/obj" file="barcode_scanner_collision_79.obj"/>
    <mesh name="barcode_scanner/barcode_scanner_collision_80" content_type="model/obj" file="barcode_scanner_collision_80.obj"/>
    <mesh name="barcode_scanner/barcode_scanner_collision_81" content_type="model/obj" file="barcode_scanner_collision_81.obj"/>
    <mesh name="barcode_scanner/barcode_scanner_collision_82" content_type="model/obj" file="barcode_scanner_collision_82.obj"/>
    <mesh name="barcode_scanner/barcode_scanner_collision_83" content_type="model/obj" file="barcode_scanner_collision_83.obj"/>
    <mesh name="barcode_scanner/barcode_scanner_collision_84" content_type="model/obj" file="barcode_scanner_collision_84.obj"/>
    <mesh name="barcode_scanner/barcode_scanner_collision_85" content_type="model/obj" file="barcode_scanner_collision_85.obj"/>
    <mesh name="barcode_scanner/barcode_scanner_collision_86" content_type="model/obj" file="barcode_scanner_collision_86.obj"/>
    <mesh name="barcode_scanner/barcode_scanner_collision_87" content_type="model/obj" file="barcode_scanner_collision_87.obj"/>
    <mesh name="barcode_scanner/barcode_scanner_collision_88" content_type="model/obj" file="barcode_scanner_collision_88.obj"/>
    <mesh name="barcode_scanner/barcode_scanner_collision_89" content_type="model/obj" file="barcode_scanner_collision_89.obj"/>
    <mesh name="barcode_scanner/barcode_scanner_collision_90" content_type="model/obj" file="barcode_scanner_collision_90.obj"/>
    <mesh name="barcode_scanner/barcode_scanner_collision_91" content_type="model/obj" file="barcode_scanner_collision_91.obj"/>
    <mesh name="barcode_scanner/barcode_scanner_collision_92" content_type="model/obj" file="barcode_scanner_collision_92.obj"/>
    <mesh name="barcode_scanner/barcode_scanner_collision_93" content_type="model/obj" file="barcode_scanner_collision_93.obj"/>
    <mesh name="003_cracker_box/003_cracker_box" content_type="model/obj" file="003_cracker_box.obj"/>
    <mesh name="003_cracker_box/003_cracker_box_collision_0" content_type="model/obj" file="003_cracker_box_collision_0.obj"/>
    <mesh name="003_cracker_box/003_cracker_box_collision_1" content_type="model/obj" file="003_cracker_box_collision_1.obj"/>
    <mesh name="004_sugar_box/004_sugar_box" content_type="model/obj" file="004_sugar_box.obj"/>
    <mesh name="004_sugar_box/004_sugar_box_collision_0" content_type="model/obj" file="004_sugar_box_collision_0.obj"/>
    <mesh name="004_sugar_box/004_sugar_box_collision_1" content_type="model/obj" file="004_sugar_box_collision_1.obj"/>
    <mesh name="005_tomato_soup_can/005_tomato_soup_can" content_type="model/obj" file="005_tomato_soup_can.obj"/>
    <mesh name="005_tomato_soup_can/005_tomato_soup_can_collision_0" content_type="model/obj" file="005_tomato_soup_can_collision_0.obj"/>
    <mesh name="005_tomato_soup_can/005_tomato_soup_can_collision_1" content_type="model/obj" file="005_tomato_soup_can_collision_1.obj"/>
    <mesh name="005_tomato_soup_can/005_tomato_soup_can_collision_2" content_type="model/obj" file="005_tomato_soup_can_collision_2.obj"/>
    <mesh name="005_tomato_soup_can/005_tomato_soup_can_collision_3" content_type="model/obj" file="005_tomato_soup_can_collision_3.obj"/>
    <mesh name="005_tomato_soup_can/005_tomato_soup_can_collision_4" content_type="model/obj" file="005_tomato_soup_can_collision_4.obj"/>
    <mesh name="005_tomato_soup_can/005_tomato_soup_can_collision_5" content_type="model/obj" file="005_tomato_soup_can_collision_5.obj"/>
    <mesh name="005_tomato_soup_can/005_tomato_soup_can_collision_6" content_type="model/obj" file="005_tomato_soup_can_collision_6.obj"/>
    <mesh name="005_tomato_soup_can/005_tomato_soup_can_collision_7" content_type="model/obj" file="005_tomato_soup_can_collision_7.obj"/>
    <mesh name="005_tomato_soup_can/005_tomato_soup_can_collision_8" content_type="model/obj" file="005_tomato_soup_can_collision_8.obj"/>
    <mesh name="005_tomato_soup_can/005_tomato_soup_can_collision_9" content_type="model/obj" file="005_tomato_soup_can_collision_9.obj"/>
    <mesh name="005_tomato_soup_can/005_tomato_soup_can_collision_10" content_type="model/obj" file="005_tomato_soup_can_collision_10.obj"/>
    <mesh name="005_tomato_soup_can/005_tomato_soup_can_collision_11" content_type="model/obj" file="005_tomato_soup_can_collision_11.obj"/>
    <mesh name="005_tomato_soup_can/005_tomato_soup_can_collision_12" content_type="model/obj" file="005_tomato_soup_can_collision_12.obj"/>
    <mesh name="005_tomato_soup_can/005_tomato_soup_can_collision_13" content_type="model/obj" file="005_tomato_soup_can_collision_13.obj"/>
    <mesh name="005_tomato_soup_can/005_tomato_soup_can_collision_14" content_type="model/obj" file="005_tomato_soup_can_collision_14.obj"/>
    <mesh name="005_tomato_soup_can/005_tomato_soup_can_collision_15" content_type="model/obj" file="005_tomato_soup_can_collision_15.obj"/>
    <mesh name="005_tomato_soup_can/005_tomato_soup_can_collision_16" content_type="model/obj" file="005_tomato_soup_can_collision_16.obj"/>
    <mesh name="005_tomato_soup_can/005_tomato_soup_can_collision_17" content_type="model/obj" file="005_tomato_soup_can_collision_17.obj"/>
    <mesh name="005_tomato_soup_can/005_tomato_soup_can_collision_18" content_type="model/obj" file="005_tomato_soup_can_collision_18.obj"/>
    <mesh name="005_tomato_soup_can/005_tomato_soup_can_collision_19" content_type="model/obj" file="005_tomato_soup_can_collision_19.obj"/>
    <mesh name="005_tomato_soup_can/005_tomato_soup_can_collision_20" content_type="model/obj" file="005_tomato_soup_can_collision_20.obj"/>
    <mesh name="005_tomato_soup_can/005_tomato_soup_can_collision_21" content_type="model/obj" file="005_tomato_soup_can_collision_21.obj"/>
    <mesh name="005_tomato_soup_can/005_tomato_soup_can_collision_22" content_type="model/obj" file="005_tomato_soup_can_collision_22.obj"/>
    <mesh name="005_tomato_soup_can/005_tomato_soup_can_collision_23" content_type="model/obj" file="005_tomato_soup_can_collision_23.obj"/>
    <mesh name="005_tomato_soup_can/005_tomato_soup_can_collision_24" content_type="model/obj" file="005_tomato_soup_can_collision_24.obj"/>
    <mesh name="005_tomato_soup_can/005_tomato_soup_can_collision_25" content_type="model/obj" file="005_tomato_soup_can_collision_25.obj"/>
    <mesh name="005_tomato_soup_can/005_tomato_soup_can_collision_26" content_type="model/obj" file="005_tomato_soup_can_collision_26.obj"/>
    <mesh name="005_tomato_soup_can/005_tomato_soup_can_collision_27" content_type="model/obj" file="005_tomato_soup_can_collision_27.obj"/>
    <mesh name="005_tomato_soup_can/005_tomato_soup_can_collision_28" content_type="model/obj" file="005_tomato_soup_can_collision_28.obj"/>
    <mesh name="005_tomato_soup_can/005_tomato_soup_can_collision_29" content_type="model/obj" file="005_tomato_soup_can_collision_29.obj"/>
    <mesh name="005_tomato_soup_can/005_tomato_soup_can_collision_30" content_type="model/obj" file="005_tomato_soup_can_collision_30.obj"/>
    <mesh name="005_tomato_soup_can/005_tomato_soup_can_collision_31" content_type="model/obj" file="005_tomato_soup_can_collision_31.obj"/>
    <mesh name="005_tomato_soup_can/005_tomato_soup_can_collision_32" content_type="model/obj" file="005_tomato_soup_can_collision_32.obj"/>
    <mesh name="005_tomato_soup_can/005_tomato_soup_can_collision_33" content_type="model/obj" file="005_tomato_soup_can_collision_33.obj"/>
    <mesh name="005_tomato_soup_can/005_tomato_soup_can_collision_34" content_type="model/obj" file="005_tomato_soup_can_collision_34.obj"/>
    <mesh name="005_tomato_soup_can/005_tomato_soup_can_collision_35" content_type="model/obj" file="005_tomato_soup_can_collision_35.obj"/>
    <mesh name="005_tomato_soup_can/005_tomato_soup_can_collision_36" content_type="model/obj" file="005_tomato_soup_can_collision_36.obj"/>
    <mesh name="005_tomato_soup_can/005_tomato_soup_can_collision_37" content_type="model/obj" file="005_tomato_soup_can_collision_37.obj"/>
    <mesh name="005_tomato_soup_can/005_tomato_soup_can_collision_38" content_type="model/obj" file="005_tomato_soup_can_collision_38.obj"/>
    <mesh name="005_tomato_soup_can/005_tomato_soup_can_collision_39" content_type="model/obj" file="005_tomato_soup_can_collision_39.obj"/>
    <mesh name="005_tomato_soup_can/005_tomato_soup_can_collision_40" content_type="model/obj" file="005_tomato_soup_can_collision_40.obj"/>
    <mesh name="005_tomato_soup_can/005_tomato_soup_can_collision_41" content_type="model/obj" file="005_tomato_soup_can_collision_41.obj"/>
    <mesh name="006_mustard_bottle/006_mustard_bottle" content_type="model/obj" file="006_mustard_bottle.obj"/>
    <mesh name="006_mustard_bottle/006_mustard_bottle_collision_0" content_type="model/obj" file="006_mustard_bottle_collision_0.obj"/>
    <mesh name="006_mustard_bottle/006_mustard_bottle_collision_1" content_type="model/obj" file="006_mustard_bottle_collision_1.obj"/>
    <mesh name="006_mustard_bottle/006_mustard_bottle_collision_2" content_type="model/obj" file="006_mustard_bottle_collision_2.obj"/>
    <mesh name="010_potted_meat_can/010_potted_meat_can" content_type="model/obj" file="010_potted_meat_can.obj"/>
    <mesh name="010_potted_meat_can/010_potted_meat_can_collision_0" content_type="model/obj" file="010_potted_meat_can_collision_0.obj"/>
    <mesh name="010_potted_meat_can/010_potted_meat_can_collision_1" content_type="model/obj" file="010_potted_meat_can_collision_1.obj"/>
    <mesh name="010_potted_meat_can/010_potted_meat_can_collision_2" content_type="model/obj" file="010_potted_meat_can_collision_2.obj"/>
    <mesh name="010_potted_meat_can/010_potted_meat_can_collision_3" content_type="model/obj" file="010_potted_meat_can_collision_3.obj"/>
    <mesh name="010_potted_meat_can/010_potted_meat_can_collision_4" content_type="model/obj" file="010_potted_meat_can_collision_4.obj"/>
    <mesh name="010_potted_meat_can/010_potted_meat_can_collision_5" content_type="model/obj" file="010_potted_meat_can_collision_5.obj"/>
    <mesh name="010_potted_meat_can/010_potted_meat_can_collision_6" content_type="model/obj" file="010_potted_meat_can_collision_6.obj"/>
    <mesh name="010_potted_meat_can/010_potted_meat_can_collision_7" content_type="model/obj" file="010_potted_meat_can_collision_7.obj"/>
    <mesh name="010_potted_meat_can/010_potted_meat_can_collision_8" content_type="model/obj" file="010_potted_meat_can_collision_8.obj"/>
    <mesh name="010_potted_meat_can/010_potted_meat_can_collision_9" content_type="model/obj" file="010_potted_meat_can_collision_9.obj"/>
    <mesh name="010_potted_meat_can/010_potted_meat_can_collision_10" content_type="model/obj" file="010_potted_meat_can_collision_10.obj"/>
    <mesh name="010_potted_meat_can/010_potted_meat_can_collision_11" content_type="model/obj" file="010_potted_meat_can_collision_11.obj"/>
    <mesh name="010_potted_meat_can/010_potted_meat_can_collision_12" content_type="model/obj" file="010_potted_meat_can_collision_12.obj"/>
    <mesh name="010_potted_meat_can/010_potted_meat_can_collision_13" content_type="model/obj" file="010_potted_meat_can_collision_13.obj"/>
    <mesh name="010_potted_meat_can/010_potted_meat_can_collision_14" content_type="model/obj" file="010_potted_meat_can_collision_14.obj"/>
    <mesh name="010_potted_meat_can/010_potted_meat_can_collision_15" content_type="model/obj" file="010_potted_meat_can_collision_15.obj"/>
    <mesh name="010_potted_meat_can/010_potted_meat_can_collision_16" content_type="model/obj" file="010_potted_meat_can_collision_16.obj"/>
    <mesh name="010_potted_meat_can/010_potted_meat_can_collision_17" content_type="model/obj" file="010_potted_meat_can_collision_17.obj"/>
    <mesh name="010_potted_meat_can/010_potted_meat_can_collision_18" content_type="model/obj" file="010_potted_meat_can_collision_18.obj"/>
    <mesh name="010_potted_meat_can/010_potted_meat_can_collision_19" content_type="model/obj" file="010_potted_meat_can_collision_19.obj"/>
    <mesh name="010_potted_meat_can/010_potted_meat_can_collision_20" content_type="model/obj" file="010_potted_meat_can_collision_20.obj"/>
    <mesh name="010_potted_meat_can/010_potted_meat_can_collision_21" content_type="model/obj" file="010_potted_meat_can_collision_21.obj"/>
    <mesh name="010_potted_meat_can/010_potted_meat_can_collision_22" content_type="model/obj" file="010_potted_meat_can_collision_22.obj"/>
    <mesh name="010_potted_meat_can/010_potted_meat_can_collision_23" content_type="model/obj" file="010_potted_meat_can_collision_23.obj"/>
    <mesh name="010_potted_meat_can/010_potted_meat_can_collision_24" content_type="model/obj" file="010_potted_meat_can_collision_24.obj"/>
    <mesh name="010_potted_meat_can/010_potted_meat_can_collision_25" content_type="model/obj" file="010_potted_meat_can_collision_25.obj"/>
    <mesh name="010_potted_meat_can/010_potted_meat_can_collision_26" content_type="model/obj" file="010_potted_meat_can_collision_26.obj"/>
    <mesh name="010_potted_meat_can/010_potted_meat_can_collision_27" content_type="model/obj" file="010_potted_meat_can_collision_27.obj"/>
    <mesh name="010_potted_meat_can/010_potted_meat_can_collision_28" content_type="model/obj" file="010_potted_meat_can_collision_28.obj"/>
    <mesh name="010_potted_meat_can/010_potted_meat_can_collision_29" content_type="model/obj" file="010_potted_meat_can_collision_29.obj"/>
    <mesh name="010_potted_meat_can/010_potted_meat_can_collision_30" content_type="model/obj" file="010_potted_meat_can_collision_30.obj"/>
    <mesh name="021_bleach_cleanser/021_bleach_cleanser" content_type="model/obj" file="021_bleach_cleanser.obj"/>
    <mesh name="021_bleach_cleanser/021_bleach_cleanser_collision_0" content_type="model/obj" file="021_bleach_cleanser_collision_0.obj"/>
    <mesh name="021_bleach_cleanser/021_bleach_cleanser_collision_1" content_type="model/obj" file="021_bleach_cleanser_collision_1.obj"/>
    <mesh name="021_bleach_cleanser/021_bleach_cleanser_collision_2" content_type="model/obj" file="021_bleach_cleanser_collision_2.obj"/>
  </asset>

  <worldbody>
    <geom name="floor" size="0 0 0.05" pos="0 0 -0.75" type="plane" material="groundplane"/>
    <site name="grasping_area" pos="0 0.37 0" size="0.36 0.17 0.001" group="4" type="box" rgba="0 1 0 1"/>
    <light pos="0 0 2" dir="0 0 -1" type="directional"/>
    <body name="table/table">
      <geom type="mesh" rgba="1 1 1 1" mesh="table/table"/>
    </body>
    <body name="robot_torso/robot_torso">
      <geom class="robot_torso/visual" rgba="0.2 0.2 0.2 1" mesh="robot_torso/robot_torso"/>
      <geom class="robot_torso/collision" rgba="0.810333 0.748149 0.889255 1" mesh="robot_torso/robot_torso_collision_0"/>
      <geom class="robot_torso/collision" rgba="0.425018 0.99271 0.606834 1" mesh="robot_torso/robot_torso_collision_1"/>
      <geom class="robot_torso/collision" rgba="0.0518038 0.638221 0.281655 1" mesh="robot_torso/robot_torso_collision_2"/>
      <geom class="robot_torso/collision" rgba="0.295382 0.528077 0.0356248 1" mesh="robot_torso/robot_torso_collision_3"/>
      <geom class="robot_torso/collision" rgba="0.418733 0.17603 0.993524 1" mesh="robot_torso/robot_torso_collision_4"/>
      <geom class="robot_torso/collision" rgba="0.179763 0.906532 0.078263 1" mesh="robot_torso/robot_torso_collision_5"/>
      <geom class="robot_torso/collision" rgba="0.415032 0.716735 0.185851 1" mesh="robot_torso/robot_torso_collision_6"/>
      <geom class="robot_torso/collision" rgba="0.368824 0.643585 0.815355 1" mesh="robot_torso/robot_torso_collision_7"/>
      <geom class="robot_torso/collision" rgba="0.762857 0.817608 0.867347 1" mesh="robot_torso/robot_torso_collision_8"/>
      <geom class="robot_torso/collision" rgba="0.586367 0.0670572 0.0518192 1" mesh="robot_torso/robot_torso_collision_9"/>
      <geom class="robot_torso/collision" rgba="0.858122 0.64965 0.933219 1" mesh="robot_torso/robot_torso_collision_10"/>
      <geom class="robot_torso/collision" rgba="0.561956 0.811561 0.377119 1" mesh="robot_torso/robot_torso_collision_11"/>
      <geom class="robot_torso/collision" rgba="0.581946 0.382172 0.88252 1" mesh="robot_torso/robot_torso_collision_12"/>
    </body>
    <body name="xarm7_left/link_base" childclass="xarm7_left/xarm7" pos="-0.05692 0 0.44761" quat="0.454519 -0.541675 -0.541675 0.454519">
      <inertial pos="-0.021131 -0.0016302 0.056488" quat="0.696843 0.20176 0.10388 0.680376" mass="0.88556" diaginertia="0.00382023 0.00335282 0.00167725"/>
      <geom material="xarm7_left/white" mesh="xarm7_left/link_base"/>
      <body name="xarm7_left/link1" pos="0 0 0.267">
        <inertial pos="-0.0002 0.02905 -0.01233" quat="0.978953 -0.202769 -0.00441617 -0.0227264" mass="2.382" diaginertia="0.00569127 0.00533384 0.00293865"/>
        <joint name="xarm7_left/joint1" class="xarm7_left/size1" pos="0 0 0" axis="0 0 1"/>
        <geom material="xarm7_left/white" mesh="xarm7_left/link1"/>
        <body name="xarm7_left/link2" quat="0.707107 -0.707107 0 0">
          <inertial pos="0.00022 -0.12856 0.01735" quat="0.50198 0.86483 -0.00778841 0.00483285" mass="1.869" diaginertia="0.00959898 0.00937717 0.00201315"/>
          <joint name="xarm7_left/joint2" class="xarm7_left/size1" pos="0 0 0" axis="0 0 1" range="-2.059 2.0944"/>
          <geom material="xarm7_left/white" mesh="xarm7_left/link2"/>
          <body name="xarm7_left/link3" pos="0 -0.293 0" quat="0.707107 0.707107 0 0">
            <inertial pos="0.0466 -0.02463 -0.00768" quat="0.913819 0.289775 0.281481 -0.0416455" mass="1.6383" diaginertia="0.00351721 0.00294089 0.00195868"/>
            <joint name="xarm7_left/joint3" class="xarm7_left/size2" pos="0 0 0" axis="0 0 1"/>
            <geom material="xarm7_left/white" mesh="xarm7_left/link3"/>
            <body name="xarm7_left/link4" pos="0.0525 0 0" quat="0.707107 0.707107 0 0">
              <inertial pos="0.07047 -0.11575 0.012" quat="0.422108 0.852026 -0.126025 0.282832" mass="1.7269" diaginertia="0.00657137 0.00647948 0.00186763"/>
              <joint name="xarm7_left/joint4" class="xarm7_left/size2" pos="0 0 0" axis="0 0 1" range="-0.19198 3.927"/>
              <geom material="xarm7_left/white" mesh="xarm7_left/link4"/>
              <body name="xarm7_left/link5" pos="0.0775 -0.3425 0" quat="0.707107 0.707107 0 0">
                <inertial pos="-0.00032 0.01604 -0.026" quat="0.999311 -0.0304457 0.000577067 0.0212082" mass="1.3203" diaginertia="0.00534729 0.00499076 0.0013489"/>
                <joint name="xarm7_left/joint5" class="xarm7_left/size2" pos="0 0 0" axis="0 0 1"/>
                <geom material="xarm7_left/white" mesh="xarm7_left/link5"/>
                <body name="xarm7_left/link6" quat="0.707107 0.707107 0 0">
                  <inertial pos="0.06469 0.03278 0.02141" quat="-0.217672 0.772419 0.16258 0.574069" mass="1.325" diaginertia="0.00245421 0.00221646 0.00107273"/>
                  <joint name="xarm7_left/joint6" class="xarm7_left/size3" pos="0 0 0" axis="0 0 1" range="-1.69297 3.14159"/>
                  <geom material="xarm7_left/white" mesh="xarm7_left/link6"/>
                  <body name="xarm7_left/link7" pos="0.076 0.097 0" quat="0.707107 -0.707107 0 0">
                    <inertial pos="0 -0.00677 -0.01098" quat="0.487612 0.512088 -0.512088 0.487612" mass="0.17" diaginertia="0.000132176 9.3e-05 5.85236e-05"/>
                    <joint name="xarm7_left/joint7" class="xarm7_left/size3" pos="0 0 0" axis="0 0 1"/>
                    <geom material="xarm7_left/gray" mesh="xarm7_left/end_tool"/>
                    <site name="xarm7_left/attachment_site" pos="0 0 0"/>
                    <body name="xarm7_left/mount" pos="0 0 0.01">
                      <geom size="0.042 0.005" pos="0 0 -0.005" type="cylinder" material="xarm7_left/white" rgba="0.2 0.2 0.2 1"/>
                      <body name="xarm7_left/inspire_rh56dftp_left/base_link">
                        <geom class="xarm7_left/inspire_rh56dftp_left/visual" material="xarm7_left/inspire_rh56dftp_left/white" mesh="xarm7_left/inspire_rh56dftp_left/base_link"/>
                        <geom class="xarm7_left/inspire_rh56dftp_left/collision" mass="0" material="xarm7_left/inspire_rh56dftp_left/white" mesh="xarm7_left/inspire_rh56dftp_left/base_link"/>
                        <geom class="xarm7_left/inspire_rh56dftp_left/visual_force_sensor" pos="0.00036819 0.012296 0.1196" quat="-2.59734e-06 -2.59735e-06 0.707108 0.707105" material="xarm7_left/inspire_rh56dftp_left/black" mesh="xarm7_left/inspire_rh56dftp_left/palm_force_sensor"/>
                        <geom class="xarm7_left/inspire_rh56dftp_left/collision_force_sensor" pos="0.00036819 0.012296 0.1196" quat="-2.59734e-06 -2.59735e-06 0.707108 0.707105" mass="0" material="xarm7_left/inspire_rh56dftp_left/black" mesh="xarm7_left/inspire_rh56dftp_left/palm_force_sensor"/>
                        <body name="xarm7_left/inspire_rh56dftp_left/thumb_proximal_1" pos="0.0269 0.02101 0.0689">
                          <joint name="xarm7_left/inspire_rh56dftp_left/thumb_proximal_1_joint" class="xarm7_left/inspire_rh56dftp_left/thumb_proximal_1" pos="0 0 0" axis="0 0 1"/>
                          <geom class="xarm7_left/inspire_rh56dftp_left/visual" material="xarm7_left/inspire_rh56dftp_left/white" mesh="xarm7_left/inspire_rh56dftp_left/thumb_proximal_1"/>
                          <geom class="xarm7_left/inspire_rh56dftp_left/collision" mass="0" material="xarm7_left/inspire_rh56dftp_left/white" mesh="xarm7_left/inspire_rh56dftp_left/thumb_proximal_1"/>
                          <body name="xarm7_left/inspire_rh56dftp_left/thumb_proximal_2" pos="0.0073431 0.011232 0.0052" quat="0.0922934 0.0922938 -0.701059 -0.701056">
                            <joint name="xarm7_left/inspire_rh56dftp_left/thumb_proximal_2_joint" class="xarm7_left/inspire_rh56dftp_left/thumb_proximal_2" pos="0 0 0" axis="0 0 -1"/>
                            <geom class="xarm7_left/inspire_rh56dftp_left/visual" material="xarm7_left/inspire_rh56dftp_left/white" mesh="xarm7_left/inspire_rh56dftp_left/thumb_proximal_2"/>
                            <geom class="xarm7_left/inspire_rh56dftp_left/collision" mass="0" material="xarm7_left/inspire_rh56dftp_left/white" mesh="xarm7_left/inspire_rh56dftp_left/thumb_proximal_2"/>
                            <geom class="xarm7_left/inspire_rh56dftp_left/visual_force_sensor" pos="-0.0087121 0.026305 -0.0089605" quat="0.405917 -0.578993 -0.405916 -0.578991" material="xarm7_left/inspire_rh56dftp_left/black" mesh="xarm7_left/inspire_rh56dftp_left/thumb_proximal_force_sensor"/>
                            <geom class="xarm7_left/inspire_rh56dftp_left/collision_force_sensor" pos="-0.0087121 0.026305 -0.0089605" quat="0.405917 -0.578993 -0.405916 -0.578991" mass="0" material="xarm7_left/inspire_rh56dftp_left/black" mesh="xarm7_left/inspire_rh56dftp_left/thumb_proximal_force_sensor"/>
                            <body name="xarm7_left/inspire_rh56dftp_left/thumb_middle" pos="-0.031403 0.021069 -0.001299">
                              <joint name="xarm7_left/inspire_rh56dftp_left/thumb_middle_joint" class="xarm7_left/inspire_rh56dftp_left/thumb_middle" pos="0 0 0" axis="0 0 -1"/>
                              <geom class="xarm7_left/inspire_rh56dftp_left/visual" material="xarm7_left/inspire_rh56dftp_left/white" mesh="xarm7_left/inspire_rh56dftp_left/thumb_middle"/>
                              <geom class="xarm7_left/inspire_rh56dftp_left/collision" mass="0" material="xarm7_left/inspire_rh56dftp_left/white" mesh="xarm7_left/inspire_rh56dftp_left/thumb_middle"/>
                              <geom class="xarm7_left/inspire_rh56dftp_left/visual_force_sensor" pos="-0.011771 0.01699 -0.0077514" quat="0.428302 -0.562766 -0.428175 -0.562599" material="xarm7_left/inspire_rh56dftp_left/black" mesh="xarm7_left/inspire_rh56dftp_left/thumb_middle_force_sensor"/>
                              <geom class="xarm7_left/inspire_rh56dftp_left/collision_force_sensor" pos="-0.011771 0.01699 -0.0077514" quat="0.428302 -0.562766 -0.428175 -0.562599" mass="0" material="xarm7_left/inspire_rh56dftp_left/black" mesh="xarm7_left/inspire_rh56dftp_left/thumb_middle_force_sensor"/>
                              <body name="xarm7_left/inspire_rh56dftp_left/thumb_distal" pos="-0.021903 0.012816 -0.0003">
                                <joint name="xarm7_left/inspire_rh56dftp_left/thumb_distal_joint" class="xarm7_left/inspire_rh56dftp_left/thumb_distal" pos="0 0 0" axis="0 0 -1"/>
                                <geom class="xarm7_left/inspire_rh56dftp_left/visual" material="xarm7_left/inspire_rh56dftp_left/white" mesh="xarm7_left/inspire_rh56dftp_left/thumb_distal"/>
                                <geom class="xarm7_left/inspire_rh56dftp_left/collision" mass="0" material="xarm7_left/inspire_rh56dftp_left/white" mesh="xarm7_left/inspire_rh56dftp_left/thumb_distal"/>
                                <geom class="xarm7_left/inspire_rh56dftp_left/visual_force_sensor" pos="-0.014598 0.014721 -0.0073103" quat="0.348432 -0.615302 -0.348433 -0.615299" material="xarm7_left/inspire_rh56dftp_left/black" mesh="xarm7_left/inspire_rh56dftp_left/thumb_distal_force_sensor"/>
                                <geom class="xarm7_left/inspire_rh56dftp_left/collision_force_sensor" pos="-0.014598 0.014721 -0.0073103" quat="0.348432 -0.615302 -0.348433 -0.615299" mass="0" material="xarm7_left/inspire_rh56dftp_left/black" mesh="xarm7_left/inspire_rh56dftp_left/thumb_distal_force_sensor"/>
                                <geom class="xarm7_left/inspire_rh56dftp_left/visual_force_sensor" pos="-0.028987 0.017301 -0.0073513" quat="-0.356218 0.610827 -0.356216 -0.610827" material="xarm7_left/inspire_rh56dftp_left/black" mesh="xarm7_left/inspire_rh56dftp_left/thumb_fingertip_force_sensor"/>
                                <geom class="xarm7_left/inspire_rh56dftp_left/collision_force_sensor" pos="-0.028987 0.017301 -0.0073513" quat="-0.356218 0.610827 -0.356216 -0.610827" mass="0" material="xarm7_left/inspire_rh56dftp_left/black" mesh="xarm7_left/inspire_rh56dftp_left/thumb_fingertip_force_sensor"/>
                              </body>
                            </body>
                          </body>
                        </body>
                        <body name="xarm7_left/inspire_rh56dftp_left/index_proximal" pos="0.038679 0.00056467 0.1564" quat="0.508647 0.491199 -0.491201 -0.508648">
                          <joint name="xarm7_left/inspire_rh56dftp_left/index_proximal_joint" class="xarm7_left/inspire_rh56dftp_left/proximal" pos="0 0 0" axis="0 0 1"/>
                          <geom class="xarm7_left/inspire_rh56dftp_left/visual" material="xarm7_left/inspire_rh56dftp_left/white" mesh="xarm7_left/inspire_rh56dftp_left/index_proximal"/>
                          <geom class="xarm7_left/inspire_rh56dftp_left/collision" mass="0" material="xarm7_left/inspire_rh56dftp_left/white" mesh="xarm7_left/inspire_rh56dftp_left/index_proximal"/>
                          <geom class="xarm7_left/inspire_rh56dftp_left/visual_force_sensor" pos="-0.012046 0.019649 0.006651" quat="0.701686 -0.0622873 -0.704358 -0.0873853" material="xarm7_left/inspire_rh56dftp_left/black" mesh="xarm7_left/inspire_rh56dftp_left/index_proximal_force_sensor"/>
                          <geom class="xarm7_left/inspire_rh56dftp_left/collision_force_sensor" pos="-0.012046 0.019649 0.006651" quat="0.701686 -0.0622873 -0.704358 -0.0873853" mass="0" material="xarm7_left/inspire_rh56dftp_left/black" mesh="xarm7_left/inspire_rh56dftp_left/index_proximal_force_sensor"/>
                          <body name="xarm7_left/inspire_rh56dftp_left/index_distal" pos="-0.0034259 0.032596 0.00055">
                            <joint name="xarm7_left/inspire_rh56dftp_left/index_distal_joint" class="xarm7_left/inspire_rh56dftp_left/distal" pos="0 0 0" axis="0 0 1"/>
                            <geom class="xarm7_left/inspire_rh56dftp_left/visual" material="xarm7_left/inspire_rh56dftp_left/white" mesh="xarm7_left/inspire_rh56dftp_left/index_distal"/>
                            <geom class="xarm7_left/inspire_rh56dftp_left/collision" mass="0" material="xarm7_left/inspire_rh56dftp_left/white" mesh="xarm7_left/inspire_rh56dftp_left/index_distal"/>
                            <geom class="xarm7_left/inspire_rh56dftp_left/visual_force_sensor" pos="-0.0081655 0.037446 0.0060795" quat="0.698536 0.13559 -0.693985 0.109758" material="xarm7_left/inspire_rh56dftp_left/black" mesh="xarm7_left/inspire_rh56dftp_left/index_distal_force_sensor"/>
                            <geom class="xarm7_left/inspire_rh56dftp_left/collision_force_sensor" pos="-0.0081655 0.037446 0.0060795" quat="0.698536 0.13559 -0.693985 0.109758" mass="0" material="xarm7_left/inspire_rh56dftp_left/black" mesh="xarm7_left/inspire_rh56dftp_left/index_distal_force_sensor"/>
                            <geom class="xarm7_left/inspire_rh56dftp_left/visual_force_sensor" pos="-0.0086237 0.052572 0.0060954" quat="0.658743 -0.226725 -0.669773 -0.257017" material="xarm7_left/inspire_rh56dftp_left/black" mesh="xarm7_left/inspire_rh56dftp_left/index_fingertip_force_sensor"/>
                            <geom class="xarm7_left/inspire_rh56dftp_left/collision_force_sensor" pos="-0.0086237 0.052572 0.0060954" quat="0.658743 -0.226725 -0.669773 -0.257017" mass="0" material="xarm7_left/inspire_rh56dftp_left/black" mesh="xarm7_left/inspire_rh56dftp_left/index_fingertip_force_sensor"/>
                          </body>
                        </body>
                        <body name="xarm7_left/inspire_rh56dftp_left/middle_proximal" pos="0.0171 0.00056467 0.157" quat="0.499998 0.5 -0.500002 -0.5">
                          <joint name="xarm7_left/inspire_rh56dftp_left/middle_proximal_joint" class="xarm7_left/inspire_rh56dftp_left/proximal" pos="0 0 0" axis="0 0 1"/>
                          <geom class="xarm7_left/inspire_rh56dftp_left/visual" material="xarm7_left/inspire_rh56dftp_left/white" mesh="xarm7_left/inspire_rh56dftp_left/middle_proximal"/>
                          <geom class="xarm7_left/inspire_rh56dftp_left/collision" mass="0" material="xarm7_left/inspire_rh56dftp_left/white" mesh="xarm7_left/inspire_rh56dftp_left/middle_proximal"/>
                          <geom class="xarm7_left/inspire_rh56dftp_left/visual_force_sensor" pos="-0.012046 0.019649 0.006651" quat="0.703134 -0.0748456 -0.703135 -0.0748437" material="xarm7_left/inspire_rh56dftp_left/black" mesh="xarm7_left/inspire_rh56dftp_left/middle_proximal_force_sensor"/>
                          <geom class="xarm7_left/inspire_rh56dftp_left/collision_force_sensor" pos="-0.012046 0.019649 0.006651" quat="0.703134 -0.0748456 -0.703135 -0.0748437" mass="0" material="xarm7_left/inspire_rh56dftp_left/black" mesh="xarm7_left/inspire_rh56dftp_left/middle_proximal_force_sensor"/>
                          <body name="xarm7_left/inspire_rh56dftp_left/middle_distal" pos="-0.0034259 0.032596 0.00055">
                            <joint name="xarm7_left/inspire_rh56dftp_left/middle_distal_joint" class="xarm7_left/inspire_rh56dftp_left/distal" pos="0 0 0" axis="0 0 1"/>
                            <geom class="xarm7_left/inspire_rh56dftp_left/visual" material="xarm7_left/inspire_rh56dftp_left/white" mesh="xarm7_left/inspire_rh56dftp_left/middle_distal"/>
                            <geom class="xarm7_left/inspire_rh56dftp_left/collision" mass="0" material="xarm7_left/inspire_rh56dftp_left/white" mesh="xarm7_left/inspire_rh56dftp_left/middle_distal"/>
                            <geom class="xarm7_left/inspire_rh56dftp_left/visual_force_sensor" pos="-0.009086 0.040962 0.0061003" quat="0.694858 0.131041 -0.694858 0.131044" material="xarm7_left/inspire_rh56dftp_left/black" mesh="xarm7_left/inspire_rh56dftp_left/middle_distal_force_sensor"/>
                            <geom class="xarm7_left/inspire_rh56dftp_left/collision_force_sensor" pos="-0.009086 0.040962 0.0061003" quat="0.694858 0.131041 -0.694858 0.131044" mass="0" material="xarm7_left/inspire_rh56dftp_left/black" mesh="xarm7_left/inspire_rh56dftp_left/middle_distal_force_sensor"/>
                            <geom class="xarm7_left/inspire_rh56dftp_left/visual_force_sensor" pos="-0.0098294 0.056051 0.0061006" quat="0.667288 -0.233938 -0.667289 -0.233936" material="xarm7_left/inspire_rh56dftp_left/black" mesh="xarm7_left/inspire_rh56dftp_left/middle_fingertip_force_sensor"/>
                            <geom class="xarm7_left/inspire_rh56dftp_left/collision_force_sensor" pos="-0.0098294 0.056051 0.0061006" quat="0.667288 -0.233938 -0.667289 -0.233936" mass="0" material="xarm7_left/inspire_rh56dftp_left/black" mesh="xarm7_left/inspire_rh56dftp_left/middle_fingertip_force_sensor"/>
                          </body>
                        </body>
                        <body name="xarm7_left/inspire_rh56dftp_left/ring_proximal" pos="-0.0045302 0.00056467 0.15683" quat="0.486728 0.512927 -0.512929 -0.48673">
                          <joint name="xarm7_left/inspire_rh56dftp_left/ring_proximal_joint" class="xarm7_left/inspire_rh56dftp_left/proximal" pos="0 0 0" axis="0 0 1"/>
                          <geom class="xarm7_left/inspire_rh56dftp_left/visual" material="xarm7_left/inspire_rh56dftp_left/white" mesh="xarm7_left/inspire_rh56dftp_left/ring_proximal"/>
                          <geom class="xarm7_left/inspire_rh56dftp_left/collision" mass="0" material="xarm7_left/inspire_rh56dftp_left/white" mesh="xarm7_left/inspire_rh56dftp_left/ring_proximal"/>
                          <geom class="xarm7_left/inspire_rh56dftp_left/visual_force_sensor" pos="-0.012046 0.019649 0.006651" quat="0.704887 -0.0936618 -0.700876 -0.0559809" material="xarm7_left/inspire_rh56dftp_left/black" mesh="xarm7_left/inspire_rh56dftp_left/ring_proximal_force_sensor"/>
                          <geom class="xarm7_left/inspire_rh56dftp_left/collision_force_sensor" pos="-0.012046 0.019649 0.006651" quat="0.704887 -0.0936618 -0.700876 -0.0559809" mass="0" material="xarm7_left/inspire_rh56dftp_left/black" mesh="xarm7_left/inspire_rh56dftp_left/ring_proximal_force_sensor"/>
                          <body name="xarm7_left/inspire_rh56dftp_left/ring_distal" pos="-0.0034259 0.032596 0.00055">
                            <joint name="xarm7_left/inspire_rh56dftp_left/ring_distal_joint" class="xarm7_left/inspire_rh56dftp_left/distal" pos="0 0 0" axis="0 0 1"/>
                            <geom class="xarm7_left/inspire_rh56dftp_left/visual" material="xarm7_left/inspire_rh56dftp_left/white" mesh="xarm7_left/inspire_rh56dftp_left/ring_distal"/>
                            <geom class="xarm7_left/inspire_rh56dftp_left/collision" mass="0" material="xarm7_left/inspire_rh56dftp_left/white" mesh="xarm7_left/inspire_rh56dftp_left/ring_distal"/>
                            <geom class="xarm7_left/inspire_rh56dftp_left/visual_force_sensor" pos="-0.0081655 0.037446 0.0060795" quat="0.692694 0.103257 -0.699527 0.142038" material="xarm7_left/inspire_rh56dftp_left/black" mesh="xarm7_left/inspire_rh56dftp_left/ring_distal_force_sensor"/>
                            <geom class="xarm7_left/inspire_rh56dftp_left/collision_force_sensor" pos="-0.0081655 0.037446 0.0060795" quat="0.692694 0.103257 -0.699527 0.142038" mass="0" material="xarm7_left/inspire_rh56dftp_left/black" mesh="xarm7_left/inspire_rh56dftp_left/ring_distal_force_sensor"/>
                            <geom class="xarm7_left/inspire_rh56dftp_left/visual_force_sensor" pos="-0.0086237 0.052572 0.0060954" quat="0.6723 -0.264487 -0.655779 -0.219118" material="xarm7_left/inspire_rh56dftp_left/black" mesh="xarm7_left/inspire_rh56dftp_left/ring_fingertip_force_sensor"/>
                            <geom class="xarm7_left/inspire_rh56dftp_left/collision_force_sensor" pos="-0.0086237 0.052572 0.0060954" quat="0.6723 -0.264487 -0.655779 -0.219118" mass="0" material="xarm7_left/inspire_rh56dftp_left/black" mesh="xarm7_left/inspire_rh56dftp_left/ring_fingertip_force_sensor"/>
                          </body>
                        </body>
                        <body name="xarm7_left/inspire_rh56dftp_left/little_proximal" pos="-0.025916 0.00056467 0.15365" quat="0.47315 0.525478 -0.52548 -0.473152">
                          <joint name="xarm7_left/inspire_rh56dftp_left/little_proximal_joint" class="xarm7_left/inspire_rh56dftp_left/proximal" pos="0 0 0" axis="0 0 1"/>
                          <geom class="xarm7_left/inspire_rh56dftp_left/visual" material="xarm7_left/inspire_rh56dftp_left/white" mesh="xarm7_left/inspire_rh56dftp_left/little_proximal"/>
                          <geom class="xarm7_left/inspire_rh56dftp_left/collision" mass="0" material="xarm7_left/inspire_rh56dftp_left/white" mesh="xarm7_left/inspire_rh56dftp_left/little_proximal"/>
                          <geom class="xarm7_left/inspire_rh56dftp_left/visual_force_sensor" pos="-0.012046 0.019649 0.006651" quat="0.706132 -0.112374 -0.69812 -0.0371073" material="xarm7_left/inspire_rh56dftp_left/black" mesh="xarm7_left/inspire_rh56dftp_left/little_proximal_force_sensor"/>
                          <geom class="xarm7_left/inspire_rh56dftp_left/collision_force_sensor" pos="-0.012046 0.019649 0.006651" quat="0.706132 -0.112374 -0.69812 -0.0371073" mass="0" material="xarm7_left/inspire_rh56dftp_left/black" mesh="xarm7_left/inspire_rh56dftp_left/little_proximal_force_sensor"/>
                          <body name="xarm7_left/inspire_rh56dftp_left/little_distal" pos="-0.0034259 0.032596 0.00055">
                            <joint name="xarm7_left/inspire_rh56dftp_left/little_distal_joint" class="xarm7_left/inspire_rh56dftp_left/distal" pos="0 0 0" axis="0 0 1"/>
                            <geom class="xarm7_left/inspire_rh56dftp_left/visual" material="xarm7_left/inspire_rh56dftp_left/white" mesh="xarm7_left/inspire_rh56dftp_left/little_distal"/>
                            <geom class="xarm7_left/inspire_rh56dftp_left/collision" mass="0" material="xarm7_left/inspire_rh56dftp_left/white" mesh="xarm7_left/inspire_rh56dftp_left/little_distal"/>
                            <geom class="xarm7_left/inspire_rh56dftp_left/visual_force_sensor" pos="-0.0064514 0.027683 0.0061172" quat="0.689046 0.0814204 -0.702404 0.158792" material="xarm7_left/inspire_rh56dftp_left/black" mesh="xarm7_left/inspire_rh56dftp_left/little_distal_force_sensor"/>
                            <geom class="xarm7_left/inspire_rh56dftp_left/collision_force_sensor" pos="-0.0064514 0.027683 0.0061172" quat="0.689046 0.0814204 -0.702404 0.158792" mass="0" material="xarm7_left/inspire_rh56dftp_left/black" mesh="xarm7_left/inspire_rh56dftp_left/little_distal_force_sensor"/>
                            <geom class="xarm7_left/inspire_rh56dftp_left/visual_force_sensor" pos="-0.0063973 0.042707 0.0061154" quat="0.678772 -0.289133 -0.645293 -0.198161" material="xarm7_left/inspire_rh56dftp_left/black" mesh="xarm7_left/inspire_rh56dftp_left/little_fingertip_force_sensor"/>
                            <geom class="xarm7_left/inspire_rh56dftp_left/collision_force_sensor" pos="-0.0063973 0.042707 0.0061154" quat="0.678772 -0.289133 -0.645293 -0.198161" mass="0" material="xarm7_left/inspire_rh56dftp_left/black" mesh="xarm7_left/inspire_rh56dftp_left/little_fingertip_force_sensor"/>
                          </body>
                        </body>
                      </body>
                    </body>
                  </body>
                </body>
              </body>
            </body>
          </body>
        </body>
      </body>
    </body>
    <body name="xarm7_right/link_base" childclass="xarm7_right/xarm7" pos="0.05692 0 0.44761" quat="0.454519 0.541675 0.541675 0.454519">
      <inertial pos="-0.021131 -0.0016302 0.056488" quat="0.696843 0.20176 0.10388 0.680376" mass="0.88556" diaginertia="0.00382023 0.00335282 0.00167725"/>
      <geom material="xarm7_right/white" mesh="xarm7_right/link_base"/>
      <body name="xarm7_right/link1" pos="0 0 0.267">
        <inertial pos="-0.0002 0.02905 -0.01233" quat="0.978953 -0.202769 -0.00441617 -0.0227264" mass="2.382" diaginertia="0.00569127 0.00533384 0.00293865"/>
        <joint name="xarm7_right/joint1" class="xarm7_right/size1" pos="0 0 0" axis="0 0 1"/>
        <geom material="xarm7_right/white" mesh="xarm7_right/link1"/>
        <body name="xarm7_right/link2" quat="0.707107 -0.707107 0 0">
          <inertial pos="0.00022 -0.12856 0.01735" quat="0.50198 0.86483 -0.00778841 0.00483285" mass="1.869" diaginertia="0.00959898 0.00937717 0.00201315"/>
          <joint name="xarm7_right/joint2" class="xarm7_right/size1" pos="0 0 0" axis="0 0 1" range="-2.059 2.0944"/>
          <geom material="xarm7_right/white" mesh="xarm7_right/link2"/>
          <body name="xarm7_right/link3" pos="0 -0.293 0" quat="0.707107 0.707107 0 0">
            <inertial pos="0.0466 -0.02463 -0.00768" quat="0.913819 0.289775 0.281481 -0.0416455" mass="1.6383" diaginertia="0.00351721 0.00294089 0.00195868"/>
            <joint name="xarm7_right/joint3" class="xarm7_right/size2" pos="0 0 0" axis="0 0 1"/>
            <geom material="xarm7_right/white" mesh="xarm7_right/link3"/>
            <body name="xarm7_right/link4" pos="0.0525 0 0" quat="0.707107 0.707107 0 0">
              <inertial pos="0.07047 -0.11575 0.012" quat="0.422108 0.852026 -0.126025 0.282832" mass="1.7269" diaginertia="0.00657137 0.00647948 0.00186763"/>
              <joint name="xarm7_right/joint4" class="xarm7_right/size2" pos="0 0 0" axis="0 0 1" range="-0.19198 3.927"/>
              <geom material="xarm7_right/white" mesh="xarm7_right/link4"/>
              <body name="xarm7_right/link5" pos="0.0775 -0.3425 0" quat="0.707107 0.707107 0 0">
                <inertial pos="-0.00032 0.01604 -0.026" quat="0.999311 -0.0304457 0.000577067 0.0212082" mass="1.3203" diaginertia="0.00534729 0.00499076 0.0013489"/>
                <joint name="xarm7_right/joint5" class="xarm7_right/size2" pos="0 0 0" axis="0 0 1"/>
                <geom material="xarm7_right/white" mesh="xarm7_right/link5"/>
                <body name="xarm7_right/link6" quat="0.707107 0.707107 0 0">
                  <inertial pos="0.06469 0.03278 0.02141" quat="-0.217672 0.772419 0.16258 0.574069" mass="1.325" diaginertia="0.00245421 0.00221646 0.00107273"/>
                  <joint name="xarm7_right/joint6" class="xarm7_right/size3" pos="0 0 0" axis="0 0 1" range="-1.69297 3.14159"/>
                  <geom material="xarm7_right/white" mesh="xarm7_right/link6"/>
                  <body name="xarm7_right/link7" pos="0.076 0.097 0" quat="0.707107 -0.707107 0 0">
                    <inertial pos="0 -0.00677 -0.01098" quat="0.487612 0.512088 -0.512088 0.487612" mass="0.17" diaginertia="0.000132176 9.3e-05 5.85236e-05"/>
                    <joint name="xarm7_right/joint7" class="xarm7_right/size3" pos="0 0 0" axis="0 0 1"/>
                    <geom material="xarm7_right/gray" mesh="xarm7_right/end_tool"/>
                    <site name="xarm7_right/attachment_site" pos="0 0 0"/>
                    <body name="xarm7_right/mount" pos="0 0 0.01">
                      <geom size="0.042 0.005" pos="0 0 -0.005" type="cylinder" material="xarm7_right/white" rgba="0.2 0.2 0.2 1"/>
                      <body name="xarm7_right/inspire_rh56dftp_right/base_link">
                        <geom class="xarm7_right/inspire_rh56dftp_right/visual" material="xarm7_right/inspire_rh56dftp_right/white" mesh="xarm7_right/inspire_rh56dftp_right/base_link"/>
                        <geom class="xarm7_right/inspire_rh56dftp_right/collision" mass="0" material="xarm7_right/inspire_rh56dftp_right/white" mesh="xarm7_right/inspire_rh56dftp_right/base_link"/>
                        <geom class="xarm7_right/inspire_rh56dftp_right/visual_force_sensor" pos="-0.00036819 0.012296 0.1196" quat="-2.59734e-06 -2.59735e-06 -0.707108 -0.707105" material="xarm7_right/inspire_rh56dftp_right/white" mesh="xarm7_right/inspire_rh56dftp_right/palm_force_sensor"/>
                        <geom class="xarm7_right/inspire_rh56dftp_right/collision_force_sensor" pos="-0.00036819 0.012296 0.1196" quat="-2.59734e-06 -2.59735e-06 -0.707108 -0.707105" mass="0" material="xarm7_right/inspire_rh56dftp_right/white" mesh="xarm7_right/inspire_rh56dftp_right/palm_force_sensor"/>
                        <body name="xarm7_right/inspire_rh56dftp_right/thumb_proximal_1" pos="-0.0269 0.02101 0.0689">
                          <joint name="xarm7_right/inspire_rh56dftp_right/thumb_proximal_1_joint" class="xarm7_right/inspire_rh56dftp_right/thumb_proximal_1" pos="0 0 0" axis="0 0 1"/>
                          <geom class="xarm7_right/inspire_rh56dftp_right/visual" material="xarm7_right/inspire_rh56dftp_right/white" mesh="xarm7_right/inspire_rh56dftp_right/thumb_proximal_1"/>
                          <geom class="xarm7_right/inspire_rh56dftp_right/collision" mass="0" material="xarm7_right/inspire_rh56dftp_right/white" mesh="xarm7_right/inspire_rh56dftp_right/thumb_proximal_1"/>
                          <body name="xarm7_right/inspire_rh56dftp_right/thumb_proximal_2" pos="-0.0079252 0.0090599 0.0052" quat="0.0922934 0.0922938 0.701059 0.701056">
                            <joint name="xarm7_right/inspire_rh56dftp_right/thumb_proximal_2_joint" class="xarm7_right/inspire_rh56dftp_right/thumb_proximal_2" pos="0 0 0" axis="0 0 -1"/>
                            <geom class="xarm7_right/inspire_rh56dftp_right/visual" material="xarm7_right/inspire_rh56dftp_right/white" mesh="xarm7_right/inspire_rh56dftp_right/thumb_proximal_2"/>
                            <geom class="xarm7_right/inspire_rh56dftp_right/collision" mass="0" material="xarm7_right/inspire_rh56dftp_right/white" mesh="xarm7_right/inspire_rh56dftp_right/thumb_proximal_2"/>
                            <geom class="xarm7_right/inspire_rh56dftp_right/visual_force_sensor" pos="0.0087121 0.026305 -0.0067115" quat="0.579327 -0.405437 -0.579328 -0.405439" material="xarm7_right/inspire_rh56dftp_right/white" mesh="xarm7_right/inspire_rh56dftp_right/thumb_proximal_force_sensor"/>
                            <geom class="xarm7_right/inspire_rh56dftp_right/collision_force_sensor" pos="0.0087121 0.026305 -0.0067115" quat="0.579327 -0.405437 -0.579328 -0.405439" mass="0" material="xarm7_right/inspire_rh56dftp_right/white" mesh="xarm7_right/inspire_rh56dftp_right/thumb_proximal_force_sensor"/>
                            <body name="xarm7_right/inspire_rh56dftp_right/thumb_middle" pos="0.031403 0.021069 0.00095">
                              <joint name="xarm7_right/inspire_rh56dftp_right/thumb_middle_joint" class="xarm7_right/inspire_rh56dftp_right/thumb_middle" pos="0 0 0" axis="0 0 -1"/>
                              <geom class="xarm7_right/inspire_rh56dftp_right/visual" material="xarm7_right/inspire_rh56dftp_right/white" mesh="xarm7_right/inspire_rh56dftp_right/thumb_middle"/>
                              <geom class="xarm7_right/inspire_rh56dftp_right/collision" mass="0" material="xarm7_right/inspire_rh56dftp_right/white" mesh="xarm7_right/inspire_rh56dftp_right/thumb_middle"/>
                              <geom class="xarm7_right/inspire_rh56dftp_right/visual_force_sensor" pos="0.011771 0.01699 -0.0077514" quat="-0.562601 0.428173 0.562767 0.4283" material="xarm7_right/inspire_rh56dftp_right/white" mesh="xarm7_right/inspire_rh56dftp_right/thumb_middle_force_sensor"/>
                              <geom class="xarm7_right/inspire_rh56dftp_right/collision_force_sensor" pos="0.011771 0.01699 -0.0077514" quat="-0.562601 0.428173 0.562767 0.4283" mass="0" material="xarm7_right/inspire_rh56dftp_right/white" mesh="xarm7_right/inspire_rh56dftp_right/thumb_middle_force_sensor"/>
                              <body name="xarm7_right/inspire_rh56dftp_right/thumb_distal" pos="0.021903 0.012816 -0.0003">
                                <joint name="xarm7_right/inspire_rh56dftp_right/thumb_distal_joint" class="xarm7_right/inspire_rh56dftp_right/thumb_distal" pos="0 0 0" axis="0 0 -1"/>
                                <geom class="xarm7_right/inspire_rh56dftp_right/visual" material="xarm7_right/inspire_rh56dftp_right/white" mesh="xarm7_right/inspire_rh56dftp_right/thumb_distal"/>
                                <geom class="xarm7_right/inspire_rh56dftp_right/collision" mass="0" material="xarm7_right/inspire_rh56dftp_right/white" mesh="xarm7_right/inspire_rh56dftp_right/thumb_distal"/>
                                <geom class="xarm7_right/inspire_rh56dftp_right/visual_force_sensor" pos="0.014598 0.01472 -0.0073103" quat="0.615658 -0.347798 -0.615661 -0.347797" material="xarm7_right/inspire_rh56dftp_right/white" mesh="xarm7_right/inspire_rh56dftp_right/thumb_distal_force_sensor"/>
                                <geom class="xarm7_right/inspire_rh56dftp_right/collision_force_sensor" pos="0.014598 0.01472 -0.0073103" quat="0.615658 -0.347798 -0.615661 -0.347797" mass="0" material="xarm7_right/inspire_rh56dftp_right/white" mesh="xarm7_right/inspire_rh56dftp_right/thumb_distal_force_sensor"/>
                                <geom class="xarm7_right/inspire_rh56dftp_right/visual_force_sensor" pos="0.028987 0.017301 -0.0073512" quat="0.609148 -0.359083 0.609147 0.359081" material="xarm7_right/inspire_rh56dftp_right/white" mesh="xarm7_right/inspire_rh56dftp_right/thumb_fingertip_force_sensor"/>
                                <geom class="xarm7_right/inspire_rh56dftp_right/collision_force_sensor" pos="0.028987 0.017301 -0.0073512" quat="0.609148 -0.359083 0.609147 0.359081" mass="0" material="xarm7_right/inspire_rh56dftp_right/white" mesh="xarm7_right/inspire_rh56dftp_right/thumb_fingertip_force_sensor"/>
                              </body>
                            </body>
                          </body>
                        </body>
                        <body name="xarm7_right/inspire_rh56dftp_right/index_proximal" pos="-0.038679 0.00056467 0.1564" quat="0.491197 0.508648 -0.50865 -0.491199">
                          <joint name="xarm7_right/inspire_rh56dftp_right/index_proximal_joint" class="xarm7_right/inspire_rh56dftp_right/proximal" pos="0 0 0" axis="0 0 1"/>
                          <geom class="xarm7_right/inspire_rh56dftp_right/visual" material="xarm7_right/inspire_rh56dftp_right/white" mesh="xarm7_right/inspire_rh56dftp_right/index_proximal"/>
                          <geom class="xarm7_right/inspire_rh56dftp_right/collision" mass="0" material="xarm7_right/inspire_rh56dftp_right/white" mesh="xarm7_right/inspire_rh56dftp_right/index_proximal"/>
                          <geom class="xarm7_right/inspire_rh56dftp_right/visual_force_sensor" pos="-0.012046 0.019649 -0.006651" quat="0.704358 -0.0873853 -0.701686 -0.0622873" material="xarm7_right/inspire_rh56dftp_right/white" mesh="xarm7_right/inspire_rh56dftp_right/index_proximal_force_sensor"/>
                          <geom class="xarm7_right/inspire_rh56dftp_right/collision_force_sensor" pos="-0.012046 0.019649 -0.006651" quat="0.704358 -0.0873853 -0.701686 -0.0622873" mass="0" material="xarm7_right/inspire_rh56dftp_right/white" mesh="xarm7_right/inspire_rh56dftp_right/index_proximal_force_sensor"/>
                          <body name="xarm7_right/inspire_rh56dftp_right/index_distal" pos="-0.0034259 0.032596 -0.00055">
                            <joint name="xarm7_right/inspire_rh56dftp_right/index_distal_joint" class="xarm7_right/inspire_rh56dftp_right/distal" pos="0 0 0" axis="0 0 1"/>
                            <geom class="xarm7_right/inspire_rh56dftp_right/visual" material="xarm7_right/inspire_rh56dftp_right/white" mesh="xarm7_right/inspire_rh56dftp_right/index_distal"/>
                            <geom class="xarm7_right/inspire_rh56dftp_right/collision" mass="0" material="xarm7_right/inspire_rh56dftp_right/white" mesh="xarm7_right/inspire_rh56dftp_right/index_distal"/>
                            <geom class="xarm7_right/inspire_rh56dftp_right/visual_force_sensor" pos="-0.0081655 0.037446 -0.0060795" quat="0.693985 0.109758 -0.698536 0.13559" material="xarm7_right/inspire_rh56dftp_right/white" mesh="xarm7_right/inspire_rh56dftp_right/index_distal_force_sensor"/>
                            <geom class="xarm7_right/inspire_rh56dftp_right/collision_force_sensor" pos="-0.0081655 0.037446 -0.0060795" quat="0.693985 0.109758 -0.698536 0.13559" mass="0" material="xarm7_right/inspire_rh56dftp_right/white" mesh="xarm7_right/inspire_rh56dftp_right/index_distal_force_sensor"/>
                            <geom class="xarm7_right/inspire_rh56dftp_right/visual_force_sensor" pos="-0.0086237 0.052572 -0.0060954" quat="0.66977 -0.257027 -0.658739 -0.226735" material="xarm7_right/inspire_rh56dftp_right/white" mesh="xarm7_right/inspire_rh56dftp_right/index_fingertip_force_sensor"/>
                            <geom class="xarm7_right/inspire_rh56dftp_right/collision_force_sensor" pos="-0.0086237 0.052572 -0.0060954" quat="0.66977 -0.257027 -0.658739 -0.226735" mass="0" material="xarm7_right/inspire_rh56dftp_right/white" mesh="xarm7_right/inspire_rh56dftp_right/index_fingertip_force_sensor"/>
                          </body>
                        </body>
                        <body name="xarm7_right/inspire_rh56dftp_right/middle_proximal" pos="-0.0171 0.00056467 0.157" quat="0.499998 0.5 -0.500002 -0.5">
                          <joint name="xarm7_right/inspire_rh56dftp_right/middle_proximal_joint" class="xarm7_right/inspire_rh56dftp_right/proximal" pos="0 0 0" axis="0 0 1"/>
                          <geom class="xarm7_right/inspire_rh56dftp_right/visual" material="xarm7_right/inspire_rh56dftp_right/white" mesh="xarm7_right/inspire_rh56dftp_right/middle_proximal"/>
                          <geom class="xarm7_right/inspire_rh56dftp_right/collision" mass="0" material="xarm7_right/inspire_rh56dftp_right/white" mesh="xarm7_right/inspire_rh56dftp_right/middle_proximal"/>
                          <geom class="xarm7_right/inspire_rh56dftp_right/visual_force_sensor" pos="-0.012046 0.019649 -0.006651" quat="-0.703076 0.0754056 0.703073 0.0754054" material="xarm7_right/inspire_rh56dftp_right/white" mesh="xarm7_right/inspire_rh56dftp_right/middle_proximal_force_sensor"/>
                          <geom class="xarm7_right/inspire_rh56dftp_right/collision_force_sensor" pos="-0.012046 0.019649 -0.006651" quat="-0.703076 0.0754056 0.703073 0.0754054" mass="0" material="xarm7_right/inspire_rh56dftp_right/white" mesh="xarm7_right/inspire_rh56dftp_right/middle_proximal_force_sensor"/>
                          <body name="xarm7_right/inspire_rh56dftp_right/right_middle_2" pos="-0.0034259 0.032596 -0.00055">
                            <joint name="xarm7_right/inspire_rh56dftp_right/middle_distal_joint" class="xarm7_right/inspire_rh56dftp_right/distal" pos="0 0 0" axis="0 0 1"/>
                            <geom class="xarm7_right/inspire_rh56dftp_right/visual" material="xarm7_right/inspire_rh56dftp_right/white" mesh="xarm7_right/inspire_rh56dftp_right/middle_distal"/>
                            <geom class="xarm7_right/inspire_rh56dftp_right/collision" mass="0" material="xarm7_right/inspire_rh56dftp_right/white" mesh="xarm7_right/inspire_rh56dftp_right/middle_distal"/>
                            <geom class="xarm7_right/inspire_rh56dftp_right/visual_force_sensor" pos="-0.0090859 0.040963 -0.0061003" quat="-0.695008 -0.130248 0.695006 -0.130249" material="xarm7_right/inspire_rh56dftp_right/white" mesh="xarm7_right/inspire_rh56dftp_right/middle_distal_force_sensor"/>
                            <geom class="xarm7_right/inspire_rh56dftp_right/collision_force_sensor" pos="-0.0090859 0.040963 -0.0061003" quat="-0.695008 -0.130248 0.695006 -0.130249" mass="0" material="xarm7_right/inspire_rh56dftp_right/white" mesh="xarm7_right/inspire_rh56dftp_right/middle_distal_force_sensor"/>
                            <geom class="xarm7_right/inspire_rh56dftp_right/visual_force_sensor" pos="-0.0098294 0.056051 -0.0061006" quat="-0.667101 0.234473 0.667099 0.234472" material="xarm7_right/inspire_rh56dftp_right/white" mesh="xarm7_right/inspire_rh56dftp_right/middle_fingertip_force_sensor"/>
                            <geom class="xarm7_right/inspire_rh56dftp_right/collision_force_sensor" pos="-0.0098294 0.056051 -0.0061006" quat="-0.667101 0.234473 0.667099 0.234472" mass="0" material="xarm7_right/inspire_rh56dftp_right/white" mesh="xarm7_right/inspire_rh56dftp_right/middle_fingertip_force_sensor"/>
                          </body>
                        </body>
                        <body name="xarm7_right/inspire_rh56dftp_right/ring_proximal" pos="0.0045302 0.00056467 0.15683" quat="0.512925 0.48673 -0.486732 -0.512927">
                          <joint name="xarm7_right/inspire_rh56dftp_right/ring_proximal_joint" class="xarm7_right/inspire_rh56dftp_right/proximal" pos="0 0 0" axis="0 0 1"/>
                          <geom class="xarm7_right/inspire_rh56dftp_right/visual" material="xarm7_right/inspire_rh56dftp_right/white" mesh="xarm7_right/inspire_rh56dftp_right/ring_proximal"/>
                          <geom class="xarm7_right/inspire_rh56dftp_right/collision" mass="0" material="xarm7_right/inspire_rh56dftp_right/white" mesh="xarm7_right/inspire_rh56dftp_right/ring_proximal"/>
                          <geom class="xarm7_right/inspire_rh56dftp_right/visual_force_sensor" pos="-0.0120462 0.0196485 -0.00665098" quat="0.700879 -0.0559904 -0.704887 -0.093644" material="xarm7_right/inspire_rh56dftp_right/white" mesh="xarm7_right/inspire_rh56dftp_right/ring_proximal_force_sensor"/>
                          <geom class="xarm7_right/inspire_rh56dftp_right/collision_force_sensor" pos="-0.0120462 0.0196485 -0.00665098" quat="0.700879 -0.0559904 -0.704887 -0.093644" mass="0" material="xarm7_right/inspire_rh56dftp_right/white" mesh="xarm7_right/inspire_rh56dftp_right/ring_proximal_force_sensor"/>
                          <body name="xarm7_right/inspire_rh56dftp_right/ring_distal" pos="-0.0034259 0.032596 -0.00055">
                            <joint name="xarm7_right/inspire_rh56dftp_right/ring_distal_joint" class="xarm7_right/inspire_rh56dftp_right/distal" pos="0 0 0" axis="0 0 1"/>
                            <geom class="xarm7_right/inspire_rh56dftp_right/visual" material="xarm7_right/inspire_rh56dftp_right/white" mesh="xarm7_right/inspire_rh56dftp_right/ring_distal"/>
                            <geom class="xarm7_right/inspire_rh56dftp_right/collision" mass="0" material="xarm7_right/inspire_rh56dftp_right/white" mesh="xarm7_right/inspire_rh56dftp_right/ring_distal"/>
                            <geom class="xarm7_right/inspire_rh56dftp_right/visual_force_sensor" pos="-0.00816549 0.0374458 -0.00607949" quat="0.699529 0.14203 -0.692696 0.103242" material="xarm7_right/inspire_rh56dftp_right/white" mesh="xarm7_right/inspire_rh56dftp_right/ring_distal_force_sensor"/>
                            <geom class="xarm7_right/inspire_rh56dftp_right/collision_force_sensor" pos="-0.00816549 0.0374458 -0.00607949" quat="0.699529 0.14203 -0.692696 0.103242" mass="0" material="xarm7_right/inspire_rh56dftp_right/white" mesh="xarm7_right/inspire_rh56dftp_right/ring_distal_force_sensor"/>
                            <geom class="xarm7_right/inspire_rh56dftp_right/visual_force_sensor" pos="-0.00862373 0.0525719 -0.00609539" quat="0.655775 -0.219109 -0.672303 -0.264497" material="xarm7_right/inspire_rh56dftp_right/white" mesh="xarm7_right/inspire_rh56dftp_right/ring_fingertip_force_sensor"/>
                            <geom class="xarm7_right/inspire_rh56dftp_right/collision_force_sensor" pos="-0.00862373 0.0525719 -0.00609539" quat="0.655775 -0.219109 -0.672303 -0.264497" mass="0" material="xarm7_right/inspire_rh56dftp_right/white" mesh="xarm7_right/inspire_rh56dftp_right/ring_fingertip_force_sensor"/>
                          </body>
                        </body>
                        <body name="xarm7_right/inspire_rh56dftp_right/little_proximal" pos="0.025916 0.00056467 0.15365" quat="0.525476 0.473152 -0.473154 -0.525478">
                          <joint name="xarm7_right/inspire_rh56dftp_right/little_proximal_joint" class="xarm7_right/inspire_rh56dftp_right/proximal" pos="0 0 0" axis="0 0 1"/>
                          <geom class="xarm7_right/inspire_rh56dftp_right/visual" material="xarm7_right/inspire_rh56dftp_right/white" mesh="xarm7_right/inspire_rh56dftp_right/little_proximal"/>
                          <geom class="xarm7_right/inspire_rh56dftp_right/collision" mass="0" material="xarm7_right/inspire_rh56dftp_right/white" mesh="xarm7_right/inspire_rh56dftp_right/little_proximal"/>
                          <geom class="xarm7_right/inspire_rh56dftp_right/visual_force_sensor" pos="-0.0120462 0.0196485 -0.00665098" quat="0.698121 -0.0371013 -0.706133 -0.112372" material="xarm7_right/inspire_rh56dftp_right/white" mesh="xarm7_right/inspire_rh56dftp_right/little_proximal_force_sensor"/>
                          <geom class="xarm7_right/inspire_rh56dftp_right/collision_force_sensor" pos="-0.0120462 0.0196485 -0.00665098" quat="0.698121 -0.0371013 -0.706133 -0.112372" mass="0" material="xarm7_right/inspire_rh56dftp_right/white" mesh="xarm7_right/inspire_rh56dftp_right/little_proximal_force_sensor"/>
                          <body name="xarm7_right/inspire_rh56dftp_right/little_distal" pos="-0.0034259 0.032596 -0.00055">
                            <joint name="xarm7_right/inspire_rh56dftp_right/little_distal_joint" class="xarm7_right/inspire_rh56dftp_right/distal" pos="0 0 0" axis="0 0 1"/>
                            <geom class="xarm7_right/inspire_rh56dftp_right/visual" material="xarm7_right/inspire_rh56dftp_right/white" mesh="xarm7_right/inspire_rh56dftp_right/little_distal"/>
                            <geom class="xarm7_right/inspire_rh56dftp_right/collision" mass="0" material="xarm7_right/inspire_rh56dftp_right/white" mesh="xarm7_right/inspire_rh56dftp_right/little_distal"/>
                            <geom class="xarm7_right/inspire_rh56dftp_right/visual_force_sensor" pos="-0.00645124 0.0276833 -0.00611719" quat="0.702403 0.158797 -0.689045 0.0814212" material="xarm7_right/inspire_rh56dftp_right/white" mesh="xarm7_right/inspire_rh56dftp_right/little_distal_force_sensor"/>
                            <geom class="xarm7_right/inspire_rh56dftp_right/collision_force_sensor" pos="-0.00645124 0.0276833 -0.00611719" quat="0.702403 0.158797 -0.689045 0.0814212" mass="0" material="xarm7_right/inspire_rh56dftp_right/white" mesh="xarm7_right/inspire_rh56dftp_right/little_distal_force_sensor"/>
                            <geom class="xarm7_right/inspire_rh56dftp_right/visual_force_sensor" pos="-0.00639723 0.0427069 -0.00611537" quat="0.645296 -0.19817 -0.67877 -0.289124" material="xarm7_right/inspire_rh56dftp_right/white" mesh="xarm7_right/inspire_rh56dftp_right/little_fingertip_force_sensor"/>
                            <geom class="xarm7_right/inspire_rh56dftp_right/collision_force_sensor" pos="-0.00639723 0.0427069 -0.00611537" quat="0.645296 -0.19817 -0.67877 -0.289124" mass="0" material="xarm7_right/inspire_rh56dftp_right/white" mesh="xarm7_right/inspire_rh56dftp_right/little_fingertip_force_sensor"/>
                          </body>
                        </body>
                      </body>
                    </body>
                  </body>
                </body>
              </body>
            </body>
          </body>
        </body>
      </body>
    </body>
    <body name="barcode_scanner/barcode_scanner" pos="-0.5 0.45 0.2" quat="0 0 -1 0">
      <joint type="free" limited="false" actuatorfrclimited="false"/>
      <geom class="barcode_scanner/visual" mass="0.16" material="barcode_scanner/material_0" mesh="barcode_scanner/barcode_scanner"/>
      <geom class="barcode_scanner/collision" rgba="0.199809 0.428858 0.235643 1" mesh="barcode_scanner/barcode_scanner_collision_0"/>
      <geom class="barcode_scanner/collision" rgba="0.283496 0.489137 0.980957 1" mesh="barcode_scanner/barcode_scanner_collision_1"/>
      <geom class="barcode_scanner/collision" rgba="0.455647 0.570513 0.0720773 1" mesh="barcode_scanner/barcode_scanner_collision_2"/>
      <geom class="barcode_scanner/collision" rgba="0.014428 0.73485 0.0857151 1" mesh="barcode_scanner/barcode_scanner_collision_3"/>
      <geom class="barcode_scanner/collision" rgba="0.9028 0.0425343 0.626694 1" mesh="barcode_scanner/barcode_scanner_collision_4"/>
      <geom class="barcode_scanner/collision" rgba="0.378282 0.748686 0.20059 1" mesh="barcode_scanner/barcode_scanner_collision_5"/>
      <geom class="barcode_scanner/collision" rgba="0.278397 0.118296 0.519279 1" mesh="barcode_scanner/barcode_scanner_collision_6"/>
      <geom class="barcode_scanner/collision" rgba="0.574059 0.499454 0.0755267 1" mesh="barcode_scanner/barcode_scanner_collision_7"/>
      <geom class="barcode_scanner/collision" rgba="0.136868 0.669248 0.410093 1" mesh="barcode_scanner/barcode_scanner_collision_8"/>
      <geom class="barcode_scanner/collision" rgba="0.992725 0.178318 0.0174727 1" mesh="barcode_scanner/barcode_scanner_collision_9"/>
      <geom class="barcode_scanner/collision" rgba="0.495625 0.769201 0.421754 1" mesh="barcode_scanner/barcode_scanner_collision_10"/>
      <geom class="barcode_scanner/collision" rgba="0.390227 0.592691 0.156122 1" mesh="barcode_scanner/barcode_scanner_collision_11"/>
      <geom class="barcode_scanner/collision" rgba="0.519489 0.271628 0.919006 1" mesh="barcode_scanner/barcode_scanner_collision_12"/>
      <geom class="barcode_scanner/collision" rgba="0.612074 0.466301 0.273554 1" mesh="barcode_scanner/barcode_scanner_collision_13"/>
      <geom class="barcode_scanner/collision" rgba="0.517851 0.0565815 0.147476 1" mesh="barcode_scanner/barcode_scanner_collision_14"/>
      <geom class="barcode_scanner/collision" rgba="0.642416 0.774131 0.590743 1" mesh="barcode_scanner/barcode_scanner_collision_15"/>
      <geom class="barcode_scanner/collision" rgba="0.0941505 0.88031 0.535842 1" mesh="barcode_scanner/barcode_scanner_collision_16"/>
      <geom class="barcode_scanner/collision" rgba="0.981973 0.362961 0.585457 1" mesh="barcode_scanner/barcode_scanner_collision_17"/>
      <geom class="barcode_scanner/collision" rgba="0.0345276 0.33216 0.89339 1" mesh="barcode_scanner/barcode_scanner_collision_18"/>
      <geom class="barcode_scanner/collision" rgba="0.541414 0.750644 0.769087 1" mesh="barcode_scanner/barcode_scanner_collision_19"/>
      <geom class="barcode_scanner/collision" rgba="0.549339 0.135921 0.639496 1" mesh="barcode_scanner/barcode_scanner_collision_20"/>
      <geom class="barcode_scanner/collision" rgba="0.433737 0.430828 0.38048 1" mesh="barcode_scanner/barcode_scanner_collision_21"/>
      <geom class="barcode_scanner/collision" rgba="0.0585284 0.403871 0.380641 1" mesh="barcode_scanner/barcode_scanner_collision_22"/>
      <geom class="barcode_scanner/collision" rgba="0.628962 0.0246349 0.559204 1" mesh="barcode_scanner/barcode_scanner_collision_23"/>
      <geom class="barcode_scanner/collision" rgba="0.496546 0.862616 0.988398 1" mesh="barcode_scanner/barcode_scanner_collision_24"/>
      <geom class="barcode_scanner/collision" rgba="0.923943 0.467726 0.0222158 1" mesh="barcode_scanner/barcode_scanner_collision_25"/>
      <geom class="barcode_scanner/collision" rgba="0.315407 0.115925 0.231872 1" mesh="barcode_scanner/barcode_scanner_collision_26"/>
      <geom class="barcode_scanner/collision" rgba="0.505145 0.760467 0.724409 1" mesh="barcode_scanner/barcode_scanner_collision_27"/>
      <geom class="barcode_scanner/collision" rgba="0.34173 0.531069 0.975306 1" mesh="barcode_scanner/barcode_scanner_collision_28"/>
      <geom class="barcode_scanner/collision" rgba="0.335555 0.301111 0.120006 1" mesh="barcode_scanner/barcode_scanner_collision_29"/>
      <geom class="barcode_scanner/collision" rgba="0.00955962 0.12955 0.38336 1" mesh="barcode_scanner/barcode_scanner_collision_30"/>
      <geom class="barcode_scanner/collision" rgba="0.300701 0.586581 0.268841 1" mesh="barcode_scanner/barcode_scanner_collision_31"/>
      <geom class="barcode_scanner/collision" rgba="0.240727 0.674473 0.619447 1" mesh="barcode_scanner/barcode_scanner_collision_32"/>
      <geom class="barcode_scanner/collision" rgba="0.0283139 0.932292 0.294153 1" mesh="barcode_scanner/barcode_scanner_collision_33"/>
      <geom class="barcode_scanner/collision" rgba="0.771442 0.207719 0.774625 1" mesh="barcode_scanner/barcode_scanner_collision_34"/>
      <geom class="barcode_scanner/collision" rgba="0.382378 0.245603 0.613362 1" mesh="barcode_scanner/barcode_scanner_collision_35"/>
      <geom class="barcode_scanner/collision" rgba="0.492636 0.103533 0.792907 1" mesh="barcode_scanner/barcode_scanner_collision_36"/>
      <geom class="barcode_scanner/collision" rgba="0.979119 0.541371 0.0102511 1" mesh="barcode_scanner/barcode_scanner_collision_37"/>
      <geom class="barcode_scanner/collision" rgba="0.0290707 0.634119 0.167423 1" mesh="barcode_scanner/barcode_scanner_collision_38"/>
      <geom class="barcode_scanner/collision" rgba="0.469677 0.824293 0.906172 1" mesh="barcode_scanner/barcode_scanner_collision_39"/>
      <geom class="barcode_scanner/collision" rgba="0.270966 0.129566 0.337877 1" mesh="barcode_scanner/barcode_scanner_collision_40"/>
      <geom class="barcode_scanner/collision" rgba="0.483706 0.255021 0.699077 1" mesh="barcode_scanner/barcode_scanner_collision_41"/>
      <geom class="barcode_scanner/collision" rgba="0.702013 0.580552 0.447573 1" mesh="barcode_scanner/barcode_scanner_collision_42"/>
      <geom class="barcode_scanner/collision" rgba="0.459541 0.135698 0.6968 1" mesh="barcode_scanner/barcode_scanner_collision_43"/>
      <geom class="barcode_scanner/collision" rgba="0.771379 0.591643 0.519102 1" mesh="barcode_scanner/barcode_scanner_collision_44"/>
      <geom class="barcode_scanner/collision" rgba="0.323344 0.672887 0.864672 1" mesh="barcode_scanner/barcode_scanner_collision_45"/>
      <geom class="barcode_scanner/collision" rgba="0.58051 0.693669 0.019833 1" mesh="barcode_scanner/barcode_scanner_collision_46"/>
      <geom class="barcode_scanner/collision" rgba="0.0089433 0.972893 0.694398 1" mesh="barcode_scanner/barcode_scanner_collision_47"/>
      <geom class="barcode_scanner/collision" rgba="0.930679 0.151754 0.229607 1" mesh="barcode_scanner/barcode_scanner_collision_48"/>
      <geom class="barcode_scanner/collision" rgba="0.197847 0.0943081 0.798579 1" mesh="barcode_scanner/barcode_scanner_collision_49"/>
      <geom class="barcode_scanner/collision" rgba="0.530384 0.794235 0.345149 1" mesh="barcode_scanner/barcode_scanner_collision_50"/>
      <geom class="barcode_scanner/collision" rgba="0.28072 0.974101 0.242028 1" mesh="barcode_scanner/barcode_scanner_collision_51"/>
      <geom class="barcode_scanner/collision" rgba="0.402753 0.490514 0.942343 1" mesh="barcode_scanner/barcode_scanner_collision_52"/>
      <geom class="barcode_scanner/collision" rgba="0.490251 0.203094 0.813983 1" mesh="barcode_scanner/barcode_scanner_collision_53"/>
      <geom class="barcode_scanner/collision" rgba="0.131868 0.409395 0.11954 1" mesh="barcode_scanner/barcode_scanner_collision_54"/>
      <geom class="barcode_scanner/collision" rgba="0.0365168 0.393056 0.460437 1" mesh="barcode_scanner/barcode_scanner_collision_55"/>
      <geom class="barcode_scanner/collision" rgba="0.56042 0.838943 0.948531 1" mesh="barcode_scanner/barcode_scanner_collision_56"/>
      <geom class="barcode_scanner/collision" rgba="0.421519 0.589851 0.732812 1" mesh="barcode_scanner/barcode_scanner_collision_57"/>
      <geom class="barcode_scanner/collision" rgba="0.35125 0.205838 0.166974 1" mesh="barcode_scanner/barcode_scanner_collision_58"/>
      <geom class="barcode_scanner/collision" rgba="0.395686 0.923564 0.619795 1" mesh="barcode_scanner/barcode_scanner_collision_59"/>
      <geom class="barcode_scanner/collision" rgba="0.138119 0.507201 0.58177 1" mesh="barcode_scanner/barcode_scanner_collision_60"/>
      <geom class="barcode_scanner/collision" rgba="0.402347 0.0336337 0.38372 1" mesh="barcode_scanner/barcode_scanner_collision_61"/>
      <geom class="barcode_scanner/collision" rgba="0.709248 0.648955 0.322482 1" mesh="barcode_scanner/barcode_scanner_collision_62"/>
      <geom class="barcode_scanner/collision" rgba="0.165184 0.689132 0.416818 1" mesh="barcode_scanner/barcode_scanner_collision_63"/>
      <geom class="barcode_scanner/collision" rgba="0.828994 0.613273 0.362675 1" mesh="barcode_scanner/barcode_scanner_collision_64"/>
      <geom class="barcode_scanner/collision" rgba="0.407227 0.399346 0.708363 1" mesh="barcode_scanner/barcode_scanner_collision_65"/>
      <geom class="barcode_scanner/collision" rgba="0.861717 0.29045 0.466925 1" mesh="barcode_scanner/barcode_scanner_collision_66"/>
      <geom class="barcode_scanner/collision" rgba="0.99816 0.336464 0.79642 1" mesh="barcode_scanner/barcode_scanner_collision_67"/>
      <geom class="barcode_scanner/collision" rgba="0.873346 0.254267 0.16842 1" mesh="barcode_scanner/barcode_scanner_collision_68"/>
      <geom class="barcode_scanner/collision" rgba="0.783159 0.700191 0.198051 1" mesh="barcode_scanner/barcode_scanner_collision_69"/>
      <geom class="barcode_scanner/collision" rgba="0.604453 0.799147 0.945003 1" mesh="barcode_scanner/barcode_scanner_collision_70"/>
      <geom class="barcode_scanner/collision" rgba="0.594464 0.02054 0.121673 1" mesh="barcode_scanner/barcode_scanner_collision_71"/>
      <geom class="barcode_scanner/collision" rgba="0.425414 0.822663 0.414748 1" mesh="barcode_scanner/barcode_scanner_collision_72"/>
      <geom class="barcode_scanner/collision" rgba="0.922623 0.292636 0.939077 1" mesh="barcode_scanner/barcode_scanner_collision_73"/>
      <geom class="barcode_scanner/collision" rgba="0.355121 0.828779 0.677204 1" mesh="barcode_scanner/barcode_scanner_collision_74"/>
      <geom class="barcode_scanner/collision" rgba="0.348408 0.325452 0.956979 1" mesh="barcode_scanner/barcode_scanner_collision_75"/>
      <geom class="barcode_scanner/collision" rgba="0.882635 0.259123 0.135333 1" mesh="barcode_scanner/barcode_scanner_collision_76"/>
      <geom class="barcode_scanner/collision" rgba="0.728885 0.0301918 0.300895 1" mesh="barcode_scanner/barcode_scanner_collision_77"/>
      <geom class="barcode_scanner/collision" rgba="0.66638 0.147448 0.690829 1" mesh="barcode_scanner/barcode_scanner_collision_78"/>
      <geom class="barcode_scanner/collision" rgba="0.938386 0.160053 0.35422 1" mesh="barcode_scanner/barcode_scanner_collision_79"/>
      <geom class="barcode_scanner/collision" rgba="0.864311 0.0192011 0.566238 1" mesh="barcode_scanner/barcode_scanner_collision_80"/>
      <geom class="barcode_scanner/collision" rgba="0.92556 0.233174 0.0471312 1" mesh="barcode_scanner/barcode_scanner_collision_81"/>
      <geom class="barcode_scanner/collision" rgba="0.144399 0.867684 0.954372 1" mesh="barcode_scanner/barcode_scanner_collision_82"/>
      <geom class="barcode_scanner/collision" rgba="0.147702 0.86484 0.542826 1" mesh="barcode_scanner/barcode_scanner_collision_83"/>
      <geom class="barcode_scanner/collision" rgba="0.149048 0.632643 0.397214 1" mesh="barcode_scanner/barcode_scanner_collision_84"/>
      <geom class="barcode_scanner/collision" rgba="0.249966 0.196892 0.598648 1" mesh="barcode_scanner/barcode_scanner_collision_85"/>
      <geom class="barcode_scanner/collision" rgba="0.621511 0.437421 0.462566 1" mesh="barcode_scanner/barcode_scanner_collision_86"/>
      <geom class="barcode_scanner/collision" rgba="0.172301 0.874864 0.694518 1" mesh="barcode_scanner/barcode_scanner_collision_87"/>
      <geom class="barcode_scanner/collision" rgba="0.61227 0.455772 0.595988 1" mesh="barcode_scanner/barcode_scanner_collision_88"/>
      <geom class="barcode_scanner/collision" rgba="0.50474 0.89939 0.609286 1" mesh="barcode_scanner/barcode_scanner_collision_89"/>
      <geom class="barcode_scanner/collision" rgba="0.380208 0.351761 0.53847 1" mesh="barcode_scanner/barcode_scanner_collision_90"/>
      <geom class="barcode_scanner/collision" rgba="0.149922 0.280384 0.849207 1" mesh="barcode_scanner/barcode_scanner_collision_91"/>
      <geom class="barcode_scanner/collision" rgba="0.275215 0.227223 0.960179 1" mesh="barcode_scanner/barcode_scanner_collision_92"/>
      <geom class="barcode_scanner/collision" rgba="0.335215 0.43565 0.742197 1" mesh="barcode_scanner/barcode_scanner_collision_93"/>
    </body>
    <body name="003_cracker_box/003_cracker_box" pos="0.1 0.25 0.12" quat="0.707107 0 0 0.707107">
      <joint name="003_cracker_box/003_cracker_box" type="free" limited="false" actuatorfrclimited="false"/>
      <geom name="003_cracker_box/003_cracker_box" class="003_cracker_box/visual" mass="0.411" material="003_cracker_box/material_0" mesh="003_cracker_box/003_cracker_box"/>
      <geom class="003_cracker_box/collision" mass="0" rgba="0.249101 0.929191 0.65191 1" mesh="003_cracker_box/003_cracker_box_collision_0"/>
      <geom class="003_cracker_box/collision" mass="0" rgba="0.541836 0.391923 0.252001 1" mesh="003_cracker_box/003_cracker_box_collision_1"/>
      <site name="003_cracker_box/barcode" pos="-0.010259 0.050995 -0.10498" quat="0 0.707107 0.707107 0" group="4" rgba="1 0 0 1"/>
    </body>
    <body name="004_sugar_box/004_sugar_box" pos="-0.1 0.25 0.12" quat="0.707107 0 0 0.707107">
      <joint name="004_sugar_box/004_sugar_box" type="free" limited="false" actuatorfrclimited="false"/>
      <geom name="004_sugar_box/004_sugar_box" class="004_sugar_box/visual" mass="0.514" material="004_sugar_box/material_0" mesh="004_sugar_box/004_sugar_box"/>
      <geom class="004_sugar_box/collision" mass="0" rgba="0.999692 0.619038 0.586412 1" mesh="004_sugar_box/004_sugar_box_collision_0"/>
      <geom class="004_sugar_box/collision" mass="0" rgba="0.410031 0.315642 0.0632252 1" mesh="004_sugar_box/004_sugar_box_collision_1"/>
      <site name="004_sugar_box/barcode" pos="0.004512 0.025381 -0.085659" quat="0 0.707107 0.707107 0" group="4" rgba="1 0 0 1"/>
    </body>
    <body name="005_tomato_soup_can/005_tomato_soup_can" pos="0.1 0.35 0.12" quat="0.707107 0 0 0.707107">
      <joint name="005_tomato_soup_can/005_tomato_soup_can" type="free" limited="false" actuatorfrclimited="false"/>
      <geom name="005_tomato_soup_can/005_tomato_soup_can" class="005_tomato_soup_can/visual" mass="0.349" material="005_tomato_soup_can/material_0" mesh="005_tomato_soup_can/005_tomato_soup_can"/>
      <geom class="005_tomato_soup_can/collision" mass="0" rgba="0.922632 0.988423 0.213375 1" mesh="005_tomato_soup_can/005_tomato_soup_can_collision_0"/>
      <geom class="005_tomato_soup_can/collision" mass="0" rgba="0.283777 0.157358 0.892837 1" mesh="005_tomato_soup_can/005_tomato_soup_can_collision_1"/>
      <geom class="005_tomato_soup_can/collision" mass="0" rgba="0.697698 0.770154 0.954358 1" mesh="005_tomato_soup_can/005_tomato_soup_can_collision_2"/>
      <geom class="005_tomato_soup_can/collision" mass="0" rgba="0.836257 0.0512012 0.419397 1" mesh="005_tomato_soup_can/005_tomato_soup_can_collision_3"/>
      <geom class="005_tomato_soup_can/collision" mass="0" rgba="0.834992 0.861768 0.369983 1" mesh="005_tomato_soup_can/005_tomato_soup_can_collision_4"/>
      <geom class="005_tomato_soup_can/collision" mass="0" rgba="0.488758 0.761383 0.298844 1" mesh="005_tomato_soup_can/005_tomato_soup_can_collision_5"/>
      <geom class="005_tomato_soup_can/collision" mass="0" rgba="0.32726 0.7394 0.614654 1" mesh="005_tomato_soup_can/005_tomato_soup_can_collision_6"/>
      <geom class="005_tomato_soup_can/collision" mass="0" rgba="0.407069 0.15273 0.365466 1" mesh="005_tomato_soup_can/005_tomato_soup_can_collision_7"/>
      <geom class="005_tomato_soup_can/collision" mass="0" rgba="0.651807 0.939958 0.784646 1" mesh="005_tomato_soup_can/005_tomato_soup_can_collision_8"/>
      <geom class="005_tomato_soup_can/collision" mass="0" rgba="0.0866114 0.440355 0.358717 1" mesh="005_tomato_soup_can/005_tomato_soup_can_collision_9"/>
      <geom class="005_tomato_soup_can/collision" mass="0" rgba="0.200716 0.694216 0.966823 1" mesh="005_tomato_soup_can/005_tomato_soup_can_collision_10"/>
      <geom class="005_tomato_soup_can/collision" mass="0" rgba="0.863794 0.972639 0.499556 1" mesh="005_tomato_soup_can/005_tomato_soup_can_collision_11"/>
      <geom class="005_tomato_soup_can/collision" mass="0" rgba="0.801962 0.00918897 0.310294 1" mesh="005_tomato_soup_can/005_tomato_soup_can_collision_12"/>
      <geom class="005_tomato_soup_can/collision" mass="0" rgba="0.908442 0.0159859 0.976381 1" mesh="005_tomato_soup_can/005_tomato_soup_can_collision_13"/>
      <geom class="005_tomato_soup_can/collision" mass="0" rgba="0.806631 0.419107 0.0593379 1" mesh="005_tomato_soup_can/005_tomato_soup_can_collision_14"/>
      <geom class="005_tomato_soup_can/collision" mass="0" rgba="0.0575891 0.84597 0.718877 1" mesh="005_tomato_soup_can/005_tomato_soup_can_collision_15"/>
      <geom class="005_tomato_soup_can/collision" mass="0" rgba="0.577565 0.622005 0.916261 1" mesh="005_tomato_soup_can/005_tomato_soup_can_collision_16"/>
      <geom class="005_tomato_soup_can/collision" mass="0" rgba="0.0326668 0.19298 0.226641 1" mesh="005_tomato_soup_can/005_tomato_soup_can_collision_17"/>
      <geom class="005_tomato_soup_can/collision" mass="0" rgba="0.650419 0.0809149 0.798804 1" mesh="005_tomato_soup_can/005_tomato_soup_can_collision_18"/>
      <geom class="005_tomato_soup_can/collision" mass="0" rgba="0.282999 0.497107 0.344912 1" mesh="005_tomato_soup_can/005_tomato_soup_can_collision_19"/>
      <geom class="005_tomato_soup_can/collision" mass="0" rgba="0.313107 0.625764 0.0595986 1" mesh="005_tomato_soup_can/005_tomato_soup_can_collision_20"/>
      <geom class="005_tomato_soup_can/collision" mass="0" rgba="0.541113 0.0848157 0.990331 1" mesh="005_tomato_soup_can/005_tomato_soup_can_collision_21"/>
      <geom class="005_tomato_soup_can/collision" mass="0" rgba="0.496798 0.198385 0.861611 1" mesh="005_tomato_soup_can/005_tomato_soup_can_collision_22"/>
      <geom class="005_tomato_soup_can/collision" mass="0" rgba="0.724024 0.421158 0.741513 1" mesh="005_tomato_soup_can/005_tomato_soup_can_collision_23"/>
      <geom class="005_tomato_soup_can/collision" mass="0" rgba="0.323666 0.527189 0.115839 1" mesh="005_tomato_soup_can/005_tomato_soup_can_collision_24"/>
      <geom class="005_tomato_soup_can/collision" mass="0" rgba="0.277893 0.414812 0.936595 1" mesh="005_tomato_soup_can/005_tomato_soup_can_collision_25"/>
      <geom class="005_tomato_soup_can/collision" mass="0" rgba="0.820868 0.321956 0.511852 1" mesh="005_tomato_soup_can/005_tomato_soup_can_collision_26"/>
      <geom class="005_tomato_soup_can/collision" mass="0" rgba="0.417922 0.707997 0.800826 1" mesh="005_tomato_soup_can/005_tomato_soup_can_collision_27"/>
      <geom class="005_tomato_soup_can/collision" mass="0" rgba="0.863783 0.896995 0.761762 1" mesh="005_tomato_soup_can/005_tomato_soup_can_collision_28"/>
      <geom class="005_tomato_soup_can/collision" mass="0" rgba="0.217301 0.385343 0.843033 1" mesh="005_tomato_soup_can/005_tomato_soup_can_collision_29"/>
      <geom class="005_tomato_soup_can/collision" mass="0" rgba="0.84934 0.301661 0.851701 1" mesh="005_tomato_soup_can/005_tomato_soup_can_collision_30"/>
      <geom class="005_tomato_soup_can/collision" mass="0" rgba="0.663618 0.822502 0.115449 1" mesh="005_tomato_soup_can/005_tomato_soup_can_collision_31"/>
      <geom class="005_tomato_soup_can/collision" mass="0" rgba="0.836031 0.684702 0.0787252 1" mesh="005_tomato_soup_can/005_tomato_soup_can_collision_32"/>
      <geom class="005_tomato_soup_can/collision" mass="0" rgba="0.00518074 0.902662 0.858329 1" mesh="005_tomato_soup_can/005_tomato_soup_can_collision_33"/>
      <geom class="005_tomato_soup_can/collision" mass="0" rgba="0.105222 0.638006 0.615959 1" mesh="005_tomato_soup_can/005_tomato_soup_can_collision_34"/>
      <geom class="005_tomato_soup_can/collision" mass="0" rgba="0.916527 0.351573 0.0292258 1" mesh="005_tomato_soup_can/005_tomato_soup_can_collision_35"/>
      <geom class="005_tomato_soup_can/collision" mass="0" rgba="0.267908 0.324063 0.0642242 1" mesh="005_tomato_soup_can/005_tomato_soup_can_collision_36"/>
      <geom class="005_tomato_soup_can/collision" mass="0" rgba="0.781529 0.71917 0.813987 1" mesh="005_tomato_soup_can/005_tomato_soup_can_collision_37"/>
      <geom class="005_tomato_soup_can/collision" mass="0" rgba="0.09685 0.184898 0.92482 1" mesh="005_tomato_soup_can/005_tomato_soup_can_collision_38"/>
      <geom class="005_tomato_soup_can/collision" mass="0" rgba="0.625505 0.612467 0.43454 1" mesh="005_tomato_soup_can/005_tomato_soup_can_collision_39"/>
      <geom class="005_tomato_soup_can/collision" mass="0" rgba="0.816639 0.21399 0.901151 1" mesh="005_tomato_soup_can/005_tomato_soup_can_collision_40"/>
      <geom class="005_tomato_soup_can/collision" mass="0" rgba="0.44465 0.241045 0.559097 1" mesh="005_tomato_soup_can/005_tomato_soup_can_collision_41"/>
      <site name="005_tomato_soup_can/barcode" pos="-0.025168 -0.023411 -0.028418" quat="0.653281 0.653281 -0.270598 -0.270598" group="4" rgba="1 0 0 1"/>
    </body>
    <body name="006_mustard_bottle/006_mustard_bottle" pos="-0.1 0.35 0.12" quat="0.707107 0 0 0.707107">
      <joint name="006_mustard_bottle/006_mustard_bottle" type="free" limited="false" actuatorfrclimited="false"/>
      <geom name="006_mustard_bottle/006_mustard_bottle" class="006_mustard_bottle/visual" mass="0.603" material="006_mustard_bottle/material_0" mesh="006_mustard_bottle/006_mustard_bottle"/>
      <geom class="006_mustard_bottle/collision" mass="0" rgba="0.38821 0.576541 0.319387 1" mesh="006_mustard_bottle/006_mustard_bottle_collision_0"/>
      <geom class="006_mustard_bottle/collision" mass="0" rgba="0.566641 0.282057 0.225972 1" mesh="006_mustard_bottle/006_mustard_bottle_collision_1"/>
      <geom class="006_mustard_bottle/collision" mass="0" rgba="0.689794 0.601882 0.298983 1" mesh="006_mustard_bottle/006_mustard_bottle_collision_2"/>
      <site name="006_mustard_bottle/barcode" pos="-0.026312 -0.000525 -0.043586" quat="0.5 0.5 -0.5 -0.5" group="4" rgba="1 0 0 1"/>
    </body>
    <body name="010_potted_meat_can/010_potted_meat_can" pos="0.1 0.45 0.12" quat="0.707107 0 0 0.707107">
      <joint name="010_potted_meat_can/010_potted_meat_can" type="free" limited="false" actuatorfrclimited="false"/>
      <geom name="010_potted_meat_can/010_potted_meat_can" class="010_potted_meat_can/visual" mass="0.37" material="010_potted_meat_can/material_0" mesh="010_potted_meat_can/010_potted_meat_can"/>
      <geom class="010_potted_meat_can/collision" mass="0" rgba="0.140978 0.548728 0.740018 1" mesh="010_potted_meat_can/010_potted_meat_can_collision_0"/>
      <geom class="010_potted_meat_can/collision" mass="0" rgba="0.996375 0.153295 0.377763 1" mesh="010_potted_meat_can/010_potted_meat_can_collision_1"/>
      <geom class="010_potted_meat_can/collision" mass="0" rgba="0.324653 0.862531 0.815973 1" mesh="010_potted_meat_can/010_potted_meat_can_collision_2"/>
      <geom class="010_potted_meat_can/collision" mass="0" rgba="0.134867 0.137847 0.00867373 1" mesh="010_potted_meat_can/010_potted_meat_can_collision_3"/>
      <geom class="010_potted_meat_can/collision" mass="0" rgba="0.0294025 0.225199 0.0323914 1" mesh="010_potted_meat_can/010_potted_meat_can_collision_4"/>
      <geom class="010_potted_meat_can/collision" mass="0" rgba="0.283791 0.482766 0.766075 1" mesh="010_potted_meat_can/010_potted_meat_can_collision_5"/>
      <geom class="010_potted_meat_can/collision" mass="0" rgba="0.703625 0.685334 0.605268 1" mesh="010_potted_meat_can/010_potted_meat_can_collision_6"/>
      <geom class="010_potted_meat_can/collision" mass="0" rgba="0.051141 0.649852 0.637456 1" mesh="010_potted_meat_can/010_potted_meat_can_collision_7"/>
      <geom class="010_potted_meat_can/collision" mass="0" rgba="0.0242688 0.115456 0.819789 1" mesh="010_potted_meat_can/010_potted_meat_can_collision_8"/>
      <geom class="010_potted_meat_can/collision" mass="0" rgba="0.917343 0.474672 0.373216 1" mesh="010_potted_meat_can/010_potted_meat_can_collision_9"/>
      <geom class="010_potted_meat_can/collision" mass="0" rgba="0.525886 0.952564 0.142311 1" mesh="010_potted_meat_can/010_potted_meat_can_collision_10"/>
      <geom class="010_potted_meat_can/collision" mass="0" rgba="0.98979 0.865142 0.714515 1" mesh="010_potted_meat_can/010_potted_meat_can_collision_11"/>
      <geom class="010_potted_meat_can/collision" mass="0" rgba="0.430251 0.664567 0.849209 1" mesh="010_potted_meat_can/010_potted_meat_can_collision_12"/>
      <geom class="010_potted_meat_can/collision" mass="0" rgba="0.535249 0.583063 0.423559 1" mesh="010_potted_meat_can/010_potted_meat_can_collision_13"/>
      <geom class="010_potted_meat_can/collision" mass="0" rgba="0.280697 0.529074 0.799432 1" mesh="010_potted_meat_can/010_potted_meat_can_collision_14"/>
      <geom class="010_potted_meat_can/collision" mass="0" rgba="0.881429 0.644652 0.882882 1" mesh="010_potted_meat_can/010_potted_meat_can_collision_15"/>
      <geom class="010_potted_meat_can/collision" mass="0" rgba="0.20809 0.0908652 0.877415 1" mesh="010_potted_meat_can/010_potted_meat_can_collision_16"/>
      <geom class="010_potted_meat_can/collision" mass="0" rgba="0.360719 0.921538 0.399494 1" mesh="010_potted_meat_can/010_potted_meat_can_collision_17"/>
      <geom class="010_potted_meat_can/collision" mass="0" rgba="0.270927 0.543914 0.168633 1" mesh="010_potted_meat_can/010_potted_meat_can_collision_18"/>
      <geom class="010_potted_meat_can/collision" mass="0" rgba="0.415089 0.995584 0.535899 1" mesh="010_potted_meat_can/010_potted_meat_can_collision_19"/>
      <geom class="010_potted_meat_can/collision" mass="0" rgba="0.360486 0.476814 0.666167 1" mesh="010_potted_meat_can/010_potted_meat_can_collision_20"/>
      <geom class="010_potted_meat_can/collision" mass="0" rgba="0.900937 0.474576 0.569603 1" mesh="010_potted_meat_can/010_potted_meat_can_collision_21"/>
      <geom class="010_potted_meat_can/collision" mass="0" rgba="0.279385 0.44139 0.965749 1" mesh="010_potted_meat_can/010_potted_meat_can_collision_22"/>
      <geom class="010_potted_meat_can/collision" mass="0" rgba="0.186217 0.54372 0.734645 1" mesh="010_potted_meat_can/010_potted_meat_can_collision_23"/>
      <geom class="010_potted_meat_can/collision" mass="0" rgba="0.903762 0.449551 0.0618495 1" mesh="010_potted_meat_can/010_potted_meat_can_collision_24"/>
      <geom class="010_potted_meat_can/collision" mass="0" rgba="0.587149 0.587197 0.830563 1" mesh="010_potted_meat_can/010_potted_meat_can_collision_25"/>
      <geom class="010_potted_meat_can/collision" mass="0" rgba="0.944946 0.73621 0.8104 1" mesh="010_potted_meat_can/010_potted_meat_can_collision_26"/>
      <geom class="010_potted_meat_can/collision" mass="0" rgba="0.32365 0.339449 0.133343 1" mesh="010_potted_meat_can/010_potted_meat_can_collision_27"/>
      <geom class="010_potted_meat_can/collision" mass="0" rgba="0.403414 0.129548 0.00474813 1" mesh="010_potted_meat_can/010_potted_meat_can_collision_28"/>
      <geom class="010_potted_meat_can/collision" mass="0" rgba="0.265139 0.743286 0.639472 1" mesh="010_potted_meat_can/010_potted_meat_can_collision_29"/>
      <geom class="010_potted_meat_can/collision" mass="0" rgba="0.934273 0.881614 0.984901 1" mesh="010_potted_meat_can/010_potted_meat_can_collision_30"/>
      <site name="010_potted_meat_can/barcode" pos="-0.00522 -0.047954 0.005731" quat="0.5 0.5 -0.5 0.5" group="4" rgba="1 0 0 1"/>
    </body>
    <body name="021_bleach_cleanser/021_bleach_cleanser" pos="-0.1 0.45 0.12" quat="0.707107 0 0 0.707107">
      <joint name="021_bleach_cleanser/021_bleach_cleanser" type="free" limited="false" actuatorfrclimited="false"/>
      <geom name="021_bleach_cleanser/021_bleach_cleanser" class="021_bleach_cleanser/visual" mass="1.131" material="021_bleach_cleanser/material_0" mesh="021_bleach_cleanser/021_bleach_cleanser"/>
      <geom class="021_bleach_cleanser/collision" mass="0" rgba="0.269788 0.715718 0.693721 1" mesh="021_bleach_cleanser/021_bleach_cleanser_collision_0"/>
      <geom class="021_bleach_cleanser/collision" mass="0" rgba="0.493017 0.718808 0.559562 1" mesh="021_bleach_cleanser/021_bleach_cleanser_collision_1"/>
      <geom class="021_bleach_cleanser/collision" mass="0" rgba="0.155396 0.495115 0.164694 1" mesh="021_bleach_cleanser/021_bleach_cleanser_collision_2"/>
      <site name="021_bleach_cleanser/barcode" pos="-0.031735 -0.01317 -0.073959" quat="-0.5 -0.5 0.5 0.5" group="4" rgba="1 0 0 1"/>
    </body>
    <body name="box" pos="0.485 0.37 0">
      <geom name="base" size="0.125 0.17 0.0025" pos="0 0 0.0025" type="box" rgba="0.7 0.6 0.4 1"/>
      <geom name="side_1" size="0.0025 0.17 0.1025" pos="0.1225 0 0.1075" type="box" rgba="0.7 0.6 0.4 1"/>
      <geom name="side_2" size="0.12 0.0025 0.1025" pos="0 -0.1675 0.1075" type="box" rgba="0.7 0.6 0.4 1"/>
      <geom name="side_3" size="0.0025 0.17 0.1025" pos="-0.1225 0 0.1075" type="box" rgba="0.7 0.6 0.4 1"/>
      <geom name="side_4" size="0.12 0.0025 0.1025" pos="0 0.1675 0.1075" type="box" rgba="0.7 0.6 0.4 1"/>
    </body>
  </worldbody>

  <contact>
    <exclude body1="xarm7_left/inspire_rh56dftp_left/base_link" body2="xarm7_left/inspire_rh56dftp_left/thumb_proximal_1"/>
    <exclude body1="xarm7_left/inspire_rh56dftp_left/base_link" body2="xarm7_left/inspire_rh56dftp_left/thumb_proximal_2"/>
    <exclude body1="xarm7_left/inspire_rh56dftp_left/base_link" body2="xarm7_left/inspire_rh56dftp_left/index_proximal"/>
    <exclude body1="xarm7_left/inspire_rh56dftp_left/base_link" body2="xarm7_left/inspire_rh56dftp_left/middle_proximal"/>
    <exclude body1="xarm7_left/inspire_rh56dftp_left/base_link" body2="xarm7_left/inspire_rh56dftp_left/ring_proximal"/>
    <exclude body1="xarm7_left/inspire_rh56dftp_left/base_link" body2="xarm7_left/inspire_rh56dftp_left/little_proximal"/>
    <exclude body1="xarm7_right/inspire_rh56dftp_right/base_link" body2="xarm7_right/inspire_rh56dftp_right/thumb_proximal_1"/>
    <exclude body1="xarm7_right/inspire_rh56dftp_right/base_link" body2="xarm7_right/inspire_rh56dftp_right/thumb_proximal_2"/>
    <exclude body1="xarm7_right/inspire_rh56dftp_right/base_link" body2="xarm7_right/inspire_rh56dftp_right/index_proximal"/>
    <exclude body1="xarm7_right/inspire_rh56dftp_right/base_link" body2="xarm7_right/inspire_rh56dftp_right/middle_proximal"/>
    <exclude body1="xarm7_right/inspire_rh56dftp_right/base_link" body2="xarm7_right/inspire_rh56dftp_right/ring_proximal"/>
    <exclude body1="xarm7_right/inspire_rh56dftp_right/base_link" body2="xarm7_right/inspire_rh56dftp_right/little_proximal"/>
  </contact>

  <actuator>
    <general name="xarm7_left/act1" class="xarm7_left/size1" joint="xarm7_left/joint1"/>
    <general name="xarm7_left/act2" class="xarm7_left/size1" joint="xarm7_left/joint2" ctrlrange="-2.059 2.0944"/>
    <general name="xarm7_left/act3" class="xarm7_left/size2" joint="xarm7_left/joint3"/>
    <general name="xarm7_left/act4" class="xarm7_left/size2" joint="xarm7_left/joint4" ctrlrange="-0.19198 3.927"/>
    <general name="xarm7_left/act5" class="xarm7_left/size2" joint="xarm7_left/joint5"/>
    <general name="xarm7_left/act6" class="xarm7_left/size3" joint="xarm7_left/joint6" ctrlrange="-1.69297 3.14159"/>
    <general name="xarm7_left/act7" class="xarm7_left/size3" joint="xarm7_left/joint7"/>
    <general name="xarm7_left/inspire_rh56dftp_left/thumb_proximal_1" class="xarm7_left/inspire_rh56dftp_left/thumb_proximal_1" joint="xarm7_left/inspire_rh56dftp_left/thumb_proximal_1_joint"/>
    <general name="xarm7_left/inspire_rh56dftp_left/thumb_proximal_2" class="xarm7_left/inspire_rh56dftp_left/thumb_proximal_2" joint="xarm7_left/inspire_rh56dftp_left/thumb_proximal_2_joint"/>
    <general name="xarm7_left/inspire_rh56dftp_left/thumb_middle" class="xarm7_left/inspire_rh56dftp_left/thumb_middle" joint="xarm7_left/inspire_rh56dftp_left/thumb_middle_joint"/>
    <general name="xarm7_left/inspire_rh56dftp_left/thumb_distal" class="xarm7_left/inspire_rh56dftp_left/thumb_distal" joint="xarm7_left/inspire_rh56dftp_left/thumb_distal_joint"/>
    <general name="xarm7_left/inspire_rh56dftp_left/index_proximal" class="xarm7_left/inspire_rh56dftp_left/proximal" joint="xarm7_left/inspire_rh56dftp_left/index_proximal_joint"/>
    <general name="xarm7_left/inspire_rh56dftp_left/index_distal" class="xarm7_left/inspire_rh56dftp_left/distal" joint="xarm7_left/inspire_rh56dftp_left/index_distal_joint"/>
    <general name="xarm7_left/inspire_rh56dftp_left/middle_proximal" class="xarm7_left/inspire_rh56dftp_left/proximal" joint="xarm7_left/inspire_rh56dftp_left/middle_proximal_joint"/>
    <general name="xarm7_left/inspire_rh56dftp_left/middle_distal" class="xarm7_left/inspire_rh56dftp_left/distal" joint="xarm7_left/inspire_rh56dftp_left/middle_distal_joint"/>
    <general name="xarm7_left/inspire_rh56dftp_left/ring_proximal" class="xarm7_left/inspire_rh56dftp_left/proximal" joint="xarm7_left/inspire_rh56dftp_left/ring_proximal_joint"/>
    <general name="xarm7_left/inspire_rh56dftp_left/ring_distal" class="xarm7_left/inspire_rh56dftp_left/distal" joint="xarm7_left/inspire_rh56dftp_left/ring_distal_joint"/>
    <general name="xarm7_left/inspire_rh56dftp_left/little_proximal" class="xarm7_left/inspire_rh56dftp_left/proximal" joint="xarm7_left/inspire_rh56dftp_left/little_proximal_joint"/>
    <general name="xarm7_left/inspire_rh56dftp_left/little_distal" class="xarm7_left/inspire_rh56dftp_left/distal" joint="xarm7_left/inspire_rh56dftp_left/little_distal_joint"/>
    <general name="xarm7_right/act1" class="xarm7_right/size1" joint="xarm7_right/joint1"/>
    <general name="xarm7_right/act2" class="xarm7_right/size1" joint="xarm7_right/joint2" ctrlrange="-2.059 2.0944"/>
    <general name="xarm7_right/act3" class="xarm7_right/size2" joint="xarm7_right/joint3"/>
    <general name="xarm7_right/act4" class="xarm7_right/size2" joint="xarm7_right/joint4" ctrlrange="-0.19198 3.927"/>
    <general name="xarm7_right/act5" class="xarm7_right/size2" joint="xarm7_right/joint5"/>
    <general name="xarm7_right/act6" class="xarm7_right/size3" joint="xarm7_right/joint6" ctrlrange="-1.69297 3.14159"/>
    <general name="xarm7_right/act7" class="xarm7_right/size3" joint="xarm7_right/joint7"/>
    <general name="xarm7_right/inspire_rh56dftp_right/thumb_proximal_1" class="xarm7_right/inspire_rh56dftp_right/thumb_proximal_1" joint="xarm7_right/inspire_rh56dftp_right/thumb_proximal_1_joint"/>
    <general name="xarm7_right/inspire_rh56dftp_right/thumb_proximal_2" class="xarm7_right/inspire_rh56dftp_right/thumb_proximal_2" joint="xarm7_right/inspire_rh56dftp_right/thumb_proximal_2_joint"/>
    <general name="xarm7_right/inspire_rh56dftp_right/thumb_middle" class="xarm7_right/inspire_rh56dftp_right/thumb_middle" joint="xarm7_right/inspire_rh56dftp_right/thumb_middle_joint"/>
    <general name="xarm7_right/inspire_rh56dftp_right/thumb_distal" class="xarm7_right/inspire_rh56dftp_right/thumb_distal" joint="xarm7_right/inspire_rh56dftp_right/thumb_distal_joint"/>
    <general name="xarm7_right/inspire_rh56dftp_right/index_proximal" class="xarm7_right/inspire_rh56dftp_right/proximal" joint="xarm7_right/inspire_rh56dftp_right/index_proximal_joint"/>
    <general name="xarm7_right/inspire_rh56dftp_right/index_distal" class="xarm7_right/inspire_rh56dftp_right/distal" joint="xarm7_right/inspire_rh56dftp_right/index_distal_joint"/>
    <general name="xarm7_right/inspire_rh56dftp_right/middle_proximal" class="xarm7_right/inspire_rh56dftp_right/proximal" joint="xarm7_right/inspire_rh56dftp_right/middle_proximal_joint"/>
    <general name="xarm7_right/inspire_rh56dftp_right/middle_distal" class="xarm7_right/inspire_rh56dftp_right/distal" joint="xarm7_right/inspire_rh56dftp_right/middle_distal_joint"/>
    <general name="xarm7_right/inspire_rh56dftp_right/ring_proximal" class="xarm7_right/inspire_rh56dftp_right/proximal" joint="xarm7_right/inspire_rh56dftp_right/ring_proximal_joint"/>
    <general name="xarm7_right/inspire_rh56dftp_right/ring_distal" class="xarm7_right/inspire_rh56dftp_right/distal" joint="xarm7_right/inspire_rh56dftp_right/ring_distal_joint"/>
    <general name="xarm7_right/inspire_rh56dftp_right/little_proximal" class="xarm7_right/inspire_rh56dftp_right/proximal" joint="xarm7_right/inspire_rh56dftp_right/little_proximal_joint"/>
    <general name="xarm7_right/inspire_rh56dftp_right/little_distal" class="xarm7_right/inspire_rh56dftp_right/distal" joint="xarm7_right/inspire_rh56dftp_right/little_distal_joint"/>
  </actuator>

  <keyframe>
    <key name="initial_state" qpos="0 0 0 0.523599 3.14159 0 -1.5708 1.16 0 0.5 0.5 1.44 1.1 1.44 1.1 1.44 1.1 1.44 1.1 0 0 0 0.523599 0 0 0 0 0 0 0 0 0 0 0 0 0 0 0 -0.0825745 0.360802 0.508715 -0.2468 -0.143711 -0.592187 -0.753493 0.1 0.25 0.12 0.707107 0 0 0.707107 -0.1 0.25 0.12 0.707107 0 0 0.707107 0.1 0.35 0.12 0.707107 0 0 0.707107 -0.1 0.35 0.12 0.707107 0 0 0.707107 0.1 0.45 0.12 0.707107 0 0 0.707107 -0.1 0.45 0.12 0.707107 0 0 0.707107" ctrl="0 0 0 0.523599 3.14159 0 -1.5708 1.16 0 0.5 0.5 1.44 1.1 1.44 1.1 1.44 1.1 1.44 1.1 0 0 0 0.523599 0 0 0 0 0 0 0 0 0 0 0 0 0 0 0"/>
  </keyframe>
</mujoco>
